Workbook

Sheet Performance Map
H1: RPM | I1: Torque (Nm) | K1: Torque (Nm) @10kW | L1: Torque (Nm) @20kW | M1: Torque (Nm) @30kW | N1: Torque (Nm) @40kW | O1: Torque (Nm) @50kW | P1: Torque (Nm) @60kW | Q1: Torque (Nm) @70kW | R1: Torque (Nm) @80kW | T1: Velocity (mph) | U1: Available Tractive F (N) @70kW | V1: Resistive F (N) @0° | W1: Resistive F (N) @5° | X1: Resistive F (N) @10° | Y1: Resistive F (N) @15° | Z1: Resistive F (N) @20° | AA1: Resistive F (N) @25° | AB1: Resistive F (N) @30° | AD1: G1 | AE1: Velocity (mph) | AF1: Input Torque (Nm) | AG1: Available Tractive F (N) | AI1: G2 | AJ1: Velocity (mph) | AK1: Input Torque (Nm) | AL1: Available Tractive F (N) | AN1: G3 | AO1: Velocity (mph) | AP1: Input Torque (Nm) | AQ1: Available Tractive F (N) | AS1: G4 | AT1: Velocity (mph) | AU1: Input Torque (Nm) | AV1: Available Tractive F (N) | AX1: G5 | AY1: Velocity (mph) | AZ1: Input Torque (Nm) | BA1: Available Tractive F (N)
B2: Cr | C2: 0.016 | H2: 400 | K2: =10000/($H2*PI()/30) -> 238.73241 | T2: 0 | V2: =0.5*1.2*($T2*0.44704)^2*$C$3*$C$5+$C$4*9.81*($C$2*COS(0*PI()/180)+SIN(0*PI()/180)) -> 170.92944 | W2: =0.5*1.2*($T2*0.44704)^2*$C$3*$C$5+$C$4*9.81*($C$2*COS(5*PI()/180)+SIN(5*PI()/180)) -> 1101.3716 | X2: =0.5*1.2*($T2*0.44704)^2*$C$3*$C$5+$C$4*9.81*($C$2*COS(10*PI()/180)+SIN(10*PI()/180)) -> 2023.4317 | Y2: =0.5*1.2*($T2*0.44704)^2*$C$3*$C$5+$C$4*9.81*($C$2*COS(15*PI()/180)+SIN(15*PI()/180)) -> 2930.0923 | Z2: =0.5*1.2*($T2*0.44704)^2*$C$3*$C$5+$C$4*9.81*($C$2*COS(20*PI()/180)+SIN(20*PI()/180)) -> 3814.4531 | AA2: =0.5*1.2*($T2*0.44704)^2*$C$3*$C$5+$C$4*9.81*($C$2*COS(25*PI()/180)+SIN(25*PI()/180)) -> 4669.7836 | AB2: =0.5*1.2*($T2*0.44704)^2*$C$3*$C$5+$C$4*9.81*($C$2*COS(30*PI()/180)+SIN(30*PI()/180)) -> 5489.5742 | AD2: 9 | AI2: 6 | AN2: 4 | AS2: 3 | AX2: 2.4
B3: Cd | C3: 0.321 | H3: 500 | K3: =10000/($H3*PI()/30) -> 190.98593 | T3: 3 | U3: =70000/(T3*0.44704) -> 52195.18 | V3: =0.5*1.2*($T3*0.44704)^2*$C$3*$C$5+$C$4*9.81*($C$2*COS(0*PI()/180)+SIN(0*PI()/180)) -> 171.67422 | W3: =0.5*1.2*($T3*0.44704)^2*$C$3*$C$5+$C$4*9.81*($C$2*COS(5*PI()/180)+SIN(5*PI()/180)) -> 1102.1164 | X3: =0.5*1.2*($T3*0.44704)^2*$C$3*$C$5+$C$4*9.81*($C$2*COS(10*PI()/180)+SIN(10*PI()/180)) -> 2024.1765 | Y3: =0.5*1.2*($T3*0.44704)^2*$C$3*$C$5+$C$4*9.81*($C$2*COS(15*PI()/180)+SIN(15*PI()/180)) -> 2930.8371 | Z3: =0.5*1.2*($T3*0.44704)^2*$C$3*$C$5+$C$4*9.81*($C$2*COS(20*PI()/180)+SIN(20*PI()/180)) -> 3815.1979 | AA3: =0.5*1.2*($T3*0.44704)^2*$C$3*$C$5+$C$4*9.81*($C$2*COS(25*PI()/180)+SIN(25*PI()/180)) -> 4670.5284 | AB3: =0.5*1.2*($T3*0.44704)^2*$C$3*$C$5+$C$4*9.81*($C$2*COS(30*PI()/180)+SIN(30*PI()/180)) -> 5490.319
B4: Mass (kg) | C4: 1089 | H4: 600 | K4: =10000/($H4*PI()/30) -> 159.15494 | T4: 6 | U4: =70000/(T4*0.44704) -> 26097.59 | V4: =0.5*1.2*($T4*0.44704)^2*$C$3*$C$5+$C$4*9.81*($C$2*COS(0*PI()/180)+SIN(0*PI()/180)) -> 173.90857 | W4: =0.5*1.2*($T4*0.44704)^2*$C$3*$C$5+$C$4*9.81*($C$2*COS(5*PI()/180)+SIN(5*PI()/180)) -> 1104.3508 | X4: =0.5*1.2*($T4*0.44704)^2*$C$3*$C$5+$C$4*9.81*($C$2*COS(10*PI()/180)+SIN(10*PI()/180)) -> 2026.4109 | Y4: =0.5*1.2*($T4*0.44704)^2*$C$3*$C$5+$C$4*9.81*($C$2*COS(15*PI()/180)+SIN(15*PI()/180)) -> 2933.0714 | Z4: =0.5*1.2*($T4*0.44704)^2*$C$3*$C$5+$C$4*9.81*($C$2*COS(20*PI()/180)+SIN(20*PI()/180)) -> 3817.4322 | AA4: =0.5*1.2*($T4*0.44704)^2*$C$3*$C$5+$C$4*9.81*($C$2*COS(25*PI()/180)+SIN(25*PI()/180)) -> 4672.7627 | AB4: =0.5*1.2*($T4*0.44704)^2*$C$3*$C$5+$C$4*9.81*($C$2*COS(30*PI()/180)+SIN(30*PI()/180)) -> 5492.5534
B5: Area (m2) | C5: 2.15 | H5: 700 | K5: =10000/($H5*PI()/30) -> 136.41852 | T5: 9 | U5: =70000/(T5*0.44704) -> 17398.393 | V5: =0.5*1.2*($T5*0.44704)^2*$C$3*$C$5+$C$4*9.81*($C$2*COS(0*PI()/180)+SIN(0*PI()/180)) -> 177.63249 | W5: =0.5*1.2*($T5*0.44704)^2*$C$3*$C$5+$C$4*9.81*($C$2*COS(5*PI()/180)+SIN(5*PI()/180)) -> 1108.0747 | X5: =0.5*1.2*($T5*0.44704)^2*$C$3*$C$5+$C$4*9.81*($C$2*COS(10*PI()/180)+SIN(10*PI()/180)) -> 2030.1348 | Y5: =0.5*1.2*($T5*0.44704)^2*$C$3*$C$5+$C$4*9.81*($C$2*COS(15*PI()/180)+SIN(15*PI()/180)) -> 2936.7954 | Z5: =0.5*1.2*($T5*0.44704)^2*$C$3*$C$5+$C$4*9.81*($C$2*COS(20*PI()/180)+SIN(20*PI()/180)) -> 3821.1562 | AA5: =0.5*1.2*($T5*0.44704)^2*$C$3*$C$5+$C$4*9.81*($C$2*COS(25*PI()/180)+SIN(25*PI()/180)) -> 4676.4867 | AB5: =0.5*1.2*($T5*0.44704)^2*$C$3*$C$5+$C$4*9.81*($C$2*COS(30*PI()/180)+SIN(30*PI()/180)) -> 5496.2773
B6: Wheel Radius (m) | C6: =0.3075*0.95 -> 0.292125 | H6: 800 | K6: =10000/($H6*PI()/30) -> 119.36621 | T6: 12 | U6: =70000/(T6*0.44704) -> 13048.795 | V6: =0.5*1.2*($T6*0.44704)^2*$C$3*$C$5+$C$4*9.81*($C$2*COS(0*PI()/180)+SIN(0*PI()/180)) -> 182.84598 | W6: =0.5*1.2*($T6*0.44704)^2*$C$3*$C$5+$C$4*9.81*($C$2*COS(5*PI()/180)+SIN(5*PI()/180)) -> 1113.2882 | X6: =0.5*1.2*($T6*0.44704)^2*$C$3*$C$5+$C$4*9.81*($C$2*COS(10*PI()/180)+SIN(10*PI()/180)) -> 2035.3483 | Y6: =0.5*1.2*($T6*0.44704)^2*$C$3*$C$5+$C$4*9.81*($C$2*COS(15*PI()/180)+SIN(15*PI()/180)) -> 2942.0088 | Z6: =0.5*1.2*($T6*0.44704)^2*$C$3*$C$5+$C$4*9.81*($C$2*COS(20*PI()/180)+SIN(20*PI()/180)) -> 3826.3696 | AA6: =0.5*1.2*($T6*0.44704)^2*$C$3*$C$5+$C$4*9.81*($C$2*COS(25*PI()/180)+SIN(25*PI()/180)) -> 4681.7001 | AB6: =0.5*1.2*($T6*0.44704)^2*$C$3*$C$5+$C$4*9.81*($C$2*COS(30*PI()/180)+SIN(30*PI()/180)) -> 5501.4908
B7: Gradient (°) | C7: 0 | H7: 900 | K7: =10000/($H7*PI()/30) -> 106.1033 | L7: =20000/($H7*PI()/30) -> 212.20659 | T7: 15 | U7: =70000/(T7*0.44704) -> 10439.036 | V7: =0.5*1.2*($T7*0.44704)^2*$C$3*$C$5+$C$4*9.81*($C$2*COS(0*PI()/180)+SIN(0*PI()/180)) -> 189.54903 | W7: =0.5*1.2*($T7*0.44704)^2*$C$3*$C$5+$C$4*9.81*($C$2*COS(5*PI()/180)+SIN(5*PI()/180)) -> 1119.9912 | X7: =0.5*1.2*($T7*0.44704)^2*$C$3*$C$5+$C$4*9.81*($C$2*COS(10*PI()/180)+SIN(10*PI()/180)) -> 2042.0513 | Y7: =0.5*1.2*($T7*0.44704)^2*$C$3*$C$5+$C$4*9.81*($C$2*COS(15*PI()/180)+SIN(15*PI()/180)) -> 2948.7119 | Z7: =0.5*1.2*($T7*0.44704)^2*$C$3*$C$5+$C$4*9.81*($C$2*COS(20*PI()/180)+SIN(20*PI()/180)) -> 3833.0727 | AA7: =0.5*1.2*($T7*0.44704)^2*$C$3*$C$5+$C$4*9.81*($C$2*COS(25*PI()/180)+SIN(25*PI()/180)) -> 4688.4032 | AB7: =0.5*1.2*($T7*0.44704)^2*$C$3*$C$5+$C$4*9.81*($C$2*COS(30*PI()/180)+SIN(30*PI()/180)) -> 5508.1938
H8: 1000 | I8: 103.5 | K8: =10000/($H8*PI()/30) -> 95.492966 | L8: =20000/($H8*PI()/30) -> 190.98593 | T8: 18 | U8: =70000/(T8*0.44704) -> 8699.1967 | V8: =0.5*1.2*($T8*0.44704)^2*$C$3*$C$5+$C$4*9.81*($C$2*COS(0*PI()/180)+SIN(0*PI()/180)) -> 197.74164 | W8: =0.5*1.2*($T8*0.44704)^2*$C$3*$C$5+$C$4*9.81*($C$2*COS(5*PI()/180)+SIN(5*PI()/180)) -> 1128.1839 | X8: =0.5*1.2*($T8*0.44704)^2*$C$3*$C$5+$C$4*9.81*($C$2*COS(10*PI()/180)+SIN(10*PI()/180)) -> 2050.244 | Y8: =0.5*1.2*($T8*0.44704)^2*$C$3*$C$5+$C$4*9.81*($C$2*COS(15*PI()/180)+SIN(15*PI()/180)) -> 2956.9045 | Z8: =0.5*1.2*($T8*0.44704)^2*$C$3*$C$5+$C$4*9.81*($C$2*COS(20*PI()/180)+SIN(20*PI()/180)) -> 3841.2653 | AA8: =0.5*1.2*($T8*0.44704)^2*$C$3*$C$5+$C$4*9.81*($C$2*COS(25*PI()/180)+SIN(25*PI()/180)) -> 4696.5958 | AB8: =0.5*1.2*($T8*0.44704)^2*$C$3*$C$5+$C$4*9.81*($C$2*COS(30*PI()/180)+SIN(30*PI()/180)) -> 5516.3864 | AE8: =PI()/30*$H8*$C$6/AD$2*2.23649 -> 7.6018937 | AF8: =(0.5*1.2*(AE8*0.44704)^2*$C$3*$C$5+$C$4*9.81*($C$2*COS($C$7*PI()/180)+SIN($C$7*PI()/180)))*$C$6/AD$2 -> 5.7033082 | AG8: =AD$2*$I8/$C$6 -> 3188.7035 | AJ8: =PI()/30*$H8*$C$6/AI$2*2.23649 -> 11.402841 | AK8: =(0.5*1.2*(AJ8*0.44704)^2*$C$3*$C$5+$C$4*9.81*($C$2*COS($C$7*PI()/180)+SIN($C$7*PI()/180)))*$C$6/AI$2 -> 8.8460062 | AL8: =AI$2*$I8/$C$6 -> 2125.8023 | AO8: =PI()/30*$H8*$C$6/AN$2*2.23649 -> 17.104261 | AP8: =(0.5*1.2*(AO8*0.44704)^2*$C$3*$C$5+$C$4*9.81*($C$2*COS($C$7*PI()/180)+SIN($C$7*PI()/180)))*$C$6/AN$2 -> 14.251283 | AQ8: =AN$2*$I8/$C$6 -> 1417.2015 | AT8: =PI()/30*$H8*$C$6/AS$2*2.23649 -> 22.805681 | AU8: =(0.5*1.2*(AT8*0.44704)^2*$C$3*$C$5+$C$4*9.81*($C$2*COS($C$7*PI()/180)+SIN($C$7*PI()/180)))*$C$6/AS$2 -> 20.835287 | AV8: =AS$2*$I8/$C$6 -> 1062.9012 | AY8: =PI()/30*$H8*$C$6/AX$2*2.23649 -> 28.507102 | AZ8: =(0.5*1.2*(AY8*0.44704)^2*$C$3*$C$5+$C$4*9.81*($C$2*COS($C$7*PI()/180)+SIN($C$7*PI()/180)))*$C$6/AX$2 -> 28.990929 | BA8: =AX$2*$I8/$C$6 -> 850.32092
H9: 1100 | I9: 117.6 | K9: =10000/($H9*PI()/30) -> 86.811787 | L9: =20000/($H9*PI()/30) -> 173.62357 | T9: 21 | U9: =70000/(T9*0.44704) -> 7456.4543 | V9: =0.5*1.2*($T9*0.44704)^2*$C$3*$C$5+$C$4*9.81*($C$2*COS(0*PI()/180)+SIN(0*PI()/180)) -> 207.42383 | W9: =0.5*1.2*($T9*0.44704)^2*$C$3*$C$5+$C$4*9.81*($C$2*COS(5*PI()/180)+SIN(5*PI()/180)) -> 1137.866 | X9: =0.5*1.2*($T9*0.44704)^2*$C$3*$C$5+$C$4*9.81*($C$2*COS(10*PI()/180)+SIN(10*PI()/180)) -> 2059.9261 | Y9: =0.5*1.2*($T9*0.44704)^2*$C$3*$C$5+$C$4*9.81*($C$2*COS(15*PI()/180)+SIN(15*PI()/180)) -> 2966.5867 | Z9: =0.5*1.2*($T9*0.44704)^2*$C$3*$C$5+$C$4*9.81*($C$2*COS(20*PI()/180)+SIN(20*PI()/180)) -> 3850.9475 | AA9: =0.5*1.2*($T9*0.44704)^2*$C$3*$C$5+$C$4*9.81*($C$2*COS(25*PI()/180)+SIN(25*PI()/180)) -> 4706.278 | AB9: =0.5*1.2*($T9*0.44704)^2*$C$3*$C$5+$C$4*9.81*($C$2*COS(30*PI()/180)+SIN(30*PI()/180)) -> 5526.0686 | AE9: =PI()/30*$H9*$C$6/AD$2*2.23649 -> 8.3620831 | AF9: =(0.5*1.2*(AE9*0.44704)^2*$C$3*$C$5+$C$4*9.81*($C$2*COS($C$7*PI()/180)+SIN($C$7*PI()/180)))*$C$6/AD$2 -> 5.7359051 | AG9: =AD$2*$I9/$C$6 -> 3623.1065 | AJ9: =PI()/30*$H9*$C$6/AI$2*2.23649 -> 12.543125 | AK9: =(0.5*1.2*(AJ9*0.44704)^2*$C$3*$C$5+$C$4*9.81*($C$2*COS($C$7*PI()/180)+SIN($C$7*PI()/180)))*$C$6/AI$2 -> 8.9560209 | AL9: =AI$2*$I9/$C$6 -> 2415.4044 | AO9: =PI()/30*$H9*$C$6/AN$2*2.23649 -> 18.814687 | AP9: =(0.5*1.2*(AO9*0.44704)^2*$C$3*$C$5+$C$4*9.81*($C$2*COS($C$7*PI()/180)+SIN($C$7*PI()/180)))*$C$6/AN$2 -> 14.622582 | AQ9: =AN$2*$I9/$C$6 -> 1610.2696 | AT9: =PI()/30*$H9*$C$6/AS$2*2.23649 -> 25.086249 | AU9: =(0.5*1.2*(AT9*0.44704)^2*$C$3*$C$5+$C$4*9.81*($C$2*COS($C$7*PI()/180)+SIN($C$7*PI()/180)))*$C$6/AS$2 -> 21.715404 | AV9: =AS$2*$I9/$C$6 -> 1207.7022 | AY9: =PI()/30*$H9*$C$6/AX$2*2.23649 -> 31.357812 | AZ9: =(0.5*1.2*(AY9*0.44704)^2*$C$3*$C$5+$C$4*9.81*($C$2*COS($C$7*PI()/180)+SIN($C$7*PI()/180)))*$C$6/AX$2 -> 30.709907 | BA9: =AX$2*$I9/$C$6 -> 966.16175
H10: 1200 | I10: 129.3 | K10: =10000/($H10*PI()/30) -> 79.577472 | L10: =20000/($H10*PI()/30) -> 159.15494 | T10: 24 | U10: =70000/(T10*0.44704) -> 6524.3975 | V10: =0.5*1.2*($T10*0.44704)^2*$C$3*$C$5+$C$4*9.81*($C$2*COS(0*PI()/180)+SIN(0*PI()/180)) -> 218.59558 | W10: =0.5*1.2*($T10*0.44704)^2*$C$3*$C$5+$C$4*9.81*($C$2*COS(5*PI()/180)+SIN(5*PI()/180)) -> 1149.0378 | X10: =0.5*1.2*($T10*0.44704)^2*$C$3*$C$5+$C$4*9.81*($C$2*COS(10*PI()/180)+SIN(10*PI()/180)) -> 2071.0979 | Y10: =0.5*1.2*($T10*0.44704)^2*$C$3*$C$5+$C$4*9.81*($C$2*COS(15*PI()/180)+SIN(15*PI()/180)) -> 2977.7585 | Z10: =0.5*1.2*($T10*0.44704)^2*$C$3*$C$5+$C$4*9.81*($C$2*COS(20*PI()/180)+SIN(20*PI()/180)) -> 3862.1192 | AA10: =0.5*1.2*($T10*0.44704)^2*$C$3*$C$5+$C$4*9.81*($C$2*COS(25*PI()/180)+SIN(25*PI()/180)) -> 4717.4497 | AB10: =0.5*1.2*($T10*0.44704)^2*$C$3*$C$5+$C$4*9.81*($C$2*COS(30*PI()/180)+SIN(30*PI()/180)) -> 5537.2404 | AE10: =PI()/30*$H10*$C$6/AD$2*2.23649 -> 9.1222725 | AF10: =(0.5*1.2*(AE10*0.44704)^2*$C$3*$C$5+$C$4*9.81*($C$2*COS($C$7*PI()/180)+SIN($C$7*PI()/180)))*$C$6/AD$2 -> 5.7716065 | AG10: =AD$2*$I10/$C$6 -> 3983.5687 | AJ10: =PI()/30*$H10*$C$6/AI$2*2.23649 -> 13.683409 | AK10: =(0.5*1.2*(AJ10*0.44704)^2*$C$3*$C$5+$C$4*9.81*($C$2*COS($C$7*PI()/180)+SIN($C$7*PI()/180)))*$C$6/AI$2 -> 9.0765131 | AL10: =AI$2*$I10/$C$6 -> 2655.7125 | AO10: =PI()/30*$H10*$C$6/AN$2*2.23649 -> 20.525113 | AP10: =(0.5*1.2*(AO10*0.44704)^2*$C$3*$C$5+$C$4*9.81*($C$2*COS($C$7*PI()/180)+SIN($C$7*PI()/180)))*$C$6/AN$2 -> 15.029243 | AQ10: =AN$2*$I10/$C$6 -> 1770.475 | AT10: =PI()/30*$H10*$C$6/AS$2*2.23649 -> 27.366817 | AU10: =(0.5*1.2*(AT10*0.44704)^2*$C$3*$C$5+$C$4*9.81*($C$2*COS($C$7*PI()/180)+SIN($C$7*PI()/180)))*$C$6/AS$2 -> 22.679342 | AV10: =AS$2*$I10/$C$6 -> 1327.8562 | AY10: =PI()/30*$H10*$C$6/AX$2*2.23649 -> 34.208522 | AZ10: =(0.5*1.2*(AY10*0.44704)^2*$C$3*$C$5+$C$4*9.81*($C$2*COS($C$7*PI()/180)+SIN($C$7*PI()/180)))*$C$6/AX$2 -> 32.592598 | BA10: =AX$2*$I10/$C$6 -> 1062.285
H11: 1300 | I11: 139.3 | K11: =10000/($H11*PI()/30) -> 73.456128 | L11: =20000/($H11*PI()/30) -> 146.91226 | T11: 27 | U11: =70000/(T11*0.44704) -> 5799.4645 | V11: =0.5*1.2*($T11*0.44704)^2*$C$3*$C$5+$C$4*9.81*($C$2*COS(0*PI()/180)+SIN(0*PI()/180)) -> 231.2569 | W11: =0.5*1.2*($T11*0.44704)^2*$C$3*$C$5+$C$4*9.81*($C$2*COS(5*PI()/180)+SIN(5*PI()/180)) -> 1161.6991 | X11: =0.5*1.2*($T11*0.44704)^2*$C$3*$C$5+$C$4*9.81*($C$2*COS(10*PI()/180)+SIN(10*PI()/180)) -> 2083.7592 | Y11: =0.5*1.2*($T11*0.44704)^2*$C$3*$C$5+$C$4*9.81*($C$2*COS(15*PI()/180)+SIN(15*PI()/180)) -> 2990.4198 | Z11: =0.5*1.2*($T11*0.44704)^2*$C$3*$C$5+$C$4*9.81*($C$2*COS(20*PI()/180)+SIN(20*PI()/180)) -> 3874.7806 | AA11: =0.5*1.2*($T11*0.44704)^2*$C$3*$C$5+$C$4*9.81*($C$2*COS(25*PI()/180)+SIN(25*PI()/180)) -> 4730.1111 | AB11: =0.5*1.2*($T11*0.44704)^2*$C$3*$C$5+$C$4*9.81*($C$2*COS(30*PI()/180)+SIN(30*PI()/180)) -> 5549.9017 | AE11: =PI()/30*$H11*$C$6/AD$2*2.23649 -> 9.8824619 | AF11: =(0.5*1.2*(AE11*0.44704)^2*$C$3*$C$5+$C$4*9.81*($C$2*COS($C$7*PI()/180)+SIN($C$7*PI()/180)))*$C$6/AD$2 -> 5.8104124 | AG11: =AD$2*$I11/$C$6 -> 4291.656 | AJ11: =PI()/30*$H11*$C$6/AI$2*2.23649 -> 14.823693 | AK11: =(0.5*1.2*(AJ11*0.44704)^2*$C$3*$C$5+$C$4*9.81*($C$2*COS($C$7*PI()/180)+SIN($C$7*PI()/180)))*$C$6/AI$2 -> 9.2074828 | AL11: =AI$2*$I11/$C$6 -> 2861.104 | AO11: =PI()/30*$H11*$C$6/AN$2*2.23649 -> 22.235539 | AP11: =(0.5*1.2*(AO11*0.44704)^2*$C$3*$C$5+$C$4*9.81*($C$2*COS($C$7*PI()/180)+SIN($C$7*PI()/180)))*$C$6/AN$2 -> 15.471266 | AQ11: =AN$2*$I11/$C$6 -> 1907.4027 | AT11: =PI()/30*$H11*$C$6/AS$2*2.23649 -> 29.647386 | AU11: =(0.5*1.2*(AT11*0.44704)^2*$C$3*$C$5+$C$4*9.81*($C$2*COS($C$7*PI()/180)+SIN($C$7*PI()/180)))*$C$6/AS$2 -> 23.7271 | AV11: =AS$2*$I11/$C$6 -> 1430.552 | AY11: =PI()/30*$H11*$C$6/AX$2*2.23649 -> 37.059232 | AZ11: =(0.5*1.2*(AY11*0.44704)^2*$C$3*$C$5+$C$4*9.81*($C$2*COS($C$7*PI()/180)+SIN($C$7*PI()/180)))*$C$6/AX$2 -> 34.639001 | BA11: =AX$2*$I11/$C$6 -> 1144.4416
H12: 1400 | I12: 147.8 | K12: =10000/($H12*PI()/30) -> 68.209261 | L12: =20000/($H12*PI()/30) -> 136.41852 | M12: =30000/($H12*PI()/30) -> 204.62778 | T12: 30 | U12: =70000/(T12*0.44704) -> 5219.518 | V12: =0.5*1.2*($T12*0.44704)^2*$C$3*$C$5+$C$4*9.81*($C$2*COS(0*PI()/180)+SIN(0*PI()/180)) -> 245.40779 | W12: =0.5*1.2*($T12*0.44704)^2*$C$3*$C$5+$C$4*9.81*($C$2*COS(5*PI()/180)+SIN(5*PI()/180)) -> 1175.85 | X12: =0.5*1.2*($T12*0.44704)^2*$C$3*$C$5+$C$4*9.81*($C$2*COS(10*PI()/180)+SIN(10*PI()/180)) -> 2097.9101 | Y12: =0.5*1.2*($T12*0.44704)^2*$C$3*$C$5+$C$4*9.81*($C$2*COS(15*PI()/180)+SIN(15*PI()/180)) -> 3004.5707 | Z12: =0.5*1.2*($T12*0.44704)^2*$C$3*$C$5+$C$4*9.81*($C$2*COS(20*PI()/180)+SIN(20*PI()/180)) -> 3888.9315 | AA12: =0.5*1.2*($T12*0.44704)^2*$C$3*$C$5+$C$4*9.81*($C$2*COS(25*PI()/180)+SIN(25*PI()/180)) -> 4744.262 | AB12: =0.5*1.2*($T12*0.44704)^2*$C$3*$C$5+$C$4*9.81*($C$2*COS(30*PI()/180)+SIN(30*PI()/180)) -> 5564.0526 | AE12: =PI()/30*$H12*$C$6/AD$2*2.23649 -> 10.642651 | AF12: =(0.5*1.2*(AE12*0.44704)^2*$C$3*$C$5+$C$4*9.81*($C$2*COS($C$7*PI()/180)+SIN($C$7*PI()/180)))*$C$6/AD$2 -> 5.8523227 | AG12: =AD$2*$I12/$C$6 -> 4553.5302 | AJ12: =PI()/30*$H12*$C$6/AI$2*2.23649 -> 15.963977 | AK12: =(0.5*1.2*(AJ12*0.44704)^2*$C$3*$C$5+$C$4*9.81*($C$2*COS($C$7*PI()/180)+SIN($C$7*PI()/180)))*$C$6/AI$2 -> 9.3489302 | AL12: =AI$2*$I12/$C$6 -> 3035.6868 | AO12: =PI()/30*$H12*$C$6/AN$2*2.23649 -> 23.945965 | AP12: =(0.5*1.2*(AO12*0.44704)^2*$C$3*$C$5+$C$4*9.81*($C$2*COS($C$7*PI()/180)+SIN($C$7*PI()/180)))*$C$6/AN$2 -> 15.948651 | AQ12: =AN$2*$I12/$C$6 -> 2023.7912 | AT12: =PI()/30*$H12*$C$6/AS$2*2.23649 -> 31.927954 | AU12: =(0.5*1.2*(AT12*0.44704)^2*$C$3*$C$5+$C$4*9.81*($C$2*COS($C$7*PI()/180)+SIN($C$7*PI()/180)))*$C$6/AS$2 -> 24.858679 | AV12: =AS$2*$I12/$C$6 -> 1517.8434 | AY12: =PI()/30*$H12*$C$6/AX$2*2.23649 -> 39.909942 | AZ12: =(0.5*1.2*(AY12*0.44704)^2*$C$3*$C$5+$C$4*9.81*($C$2*COS($C$7*PI()/180)+SIN($C$7*PI()/180)))*$C$6/AX$2 -> 36.849116 | BA12: =AX$2*$I12/$C$6 -> 1214.2747
H13: 1500 | I13: 155.2 | K13: =10000/($H13*PI()/30) -> 63.661977 | L13: =20000/($H13*PI()/30) -> 127.32395 | M13: =30000/($H13*PI()/30) -> 190.98593 | T13: 33 | U13: =70000/(T13*0.44704) -> 4745.0164 | V13: =0.5*1.2*($T13*0.44704)^2*$C$3*$C$5+$C$4*9.81*($C$2*COS(0*PI()/180)+SIN(0*PI()/180)) -> 261.04824 | W13: =0.5*1.2*($T13*0.44704)^2*$C$3*$C$5+$C$4*9.81*($C$2*COS(5*PI()/180)+SIN(5*PI()/180)) -> 1191.4904 | X13: =0.5*1.2*($T13*0.44704)^2*$C$3*$C$5+$C$4*9.81*($C$2*COS(10*PI()/180)+SIN(10*PI()/180)) -> 2113.5505 | Y13: =0.5*1.2*($T13*0.44704)^2*$C$3*$C$5+$C$4*9.81*($C$2*COS(15*PI()/180)+SIN(15*PI()/180)) -> 3020.2111 | Z13: =0.5*1.2*($T13*0.44704)^2*$C$3*$C$5+$C$4*9.81*($C$2*COS(20*PI()/180)+SIN(20*PI()/180)) -> 3904.5719 | AA13: =0.5*1.2*($T13*0.44704)^2*$C$3*$C$5+$C$4*9.81*($C$2*COS(25*PI()/180)+SIN(25*PI()/180)) -> 4759.9024 | AB13: =0.5*1.2*($T13*0.44704)^2*$C$3*$C$5+$C$4*9.81*($C$2*COS(30*PI()/180)+SIN(30*PI()/180)) -> 5579.693 | AE13: =PI()/30*$H13*$C$6/AD$2*2.23649 -> 11.402841 | AF13: =(0.5*1.2*(AE13*0.44704)^2*$C$3*$C$5+$C$4*9.81*($C$2*COS($C$7*PI()/180)+SIN($C$7*PI()/180)))*$C$6/AD$2 -> 5.8973375 | AG13: =AD$2*$I13/$C$6 -> 4781.5148 | AJ13: =PI()/30*$H13*$C$6/AI$2*2.23649 -> 17.104261 | AK13: =(0.5*1.2*(AJ13*0.44704)^2*$C$3*$C$5+$C$4*9.81*($C$2*COS($C$7*PI()/180)+SIN($C$7*PI()/180)))*$C$6/AI$2 -> 9.5008551 | AL13: =AI$2*$I13/$C$6 -> 3187.6765 | AO13: =PI()/30*$H13*$C$6/AN$2*2.23649 -> 25.656391 | AP13: =(0.5*1.2*(AO13*0.44704)^2*$C$3*$C$5+$C$4*9.81*($C$2*COS($C$7*PI()/180)+SIN($C$7*PI()/180)))*$C$6/AN$2 -> 16.461398 | AQ13: =AN$2*$I13/$C$6 -> 2125.1177 | AT13: =PI()/30*$H13*$C$6/AS$2*2.23649 -> 34.208522 | AU13: =(0.5*1.2*(AT13*0.44704)^2*$C$3*$C$5+$C$4*9.81*($C$2*COS($C$7*PI()/180)+SIN($C$7*PI()/180)))*$C$6/AS$2 -> 26.074078 | AV13: =AS$2*$I13/$C$6 -> 1593.8383 | AY13: =PI()/30*$H13*$C$6/AX$2*2.23649 -> 42.760652 | AZ13: =(0.5*1.2*(AY13*0.44704)^2*$C$3*$C$5+$C$4*9.81*($C$2*COS($C$7*PI()/180)+SIN($C$7*PI()/180)))*$C$6/AX$2 -> 39.222943 | BA13: =AX$2*$I13/$C$6 -> 1275.0706
H14: 1600 | I14: 161.7 | K14: =10000/($H14*PI()/30) -> 59.683104 | L14: =20000/($H14*PI()/30) -> 119.36621 | M14: =30000/($H14*PI()/30) -> 179.04931 | T14: 36 | U14: =70000/(T14*0.44704) -> 4349.5983 | V14: =0.5*1.2*($T14*0.44704)^2*$C$3*$C$5+$C$4*9.81*($C$2*COS(0*PI()/180)+SIN(0*PI()/180)) -> 278.17826 | W14: =0.5*1.2*($T14*0.44704)^2*$C$3*$C$5+$C$4*9.81*($C$2*COS(5*PI()/180)+SIN(5*PI()/180)) -> 1208.6205 | X14: =0.5*1.2*($T14*0.44704)^2*$C$3*$C$5+$C$4*9.81*($C$2*COS(10*PI()/180)+SIN(10*PI()/180)) -> 2130.6806 | Y14: =0.5*1.2*($T14*0.44704)^2*$C$3*$C$5+$C$4*9.81*($C$2*COS(15*PI()/180)+SIN(15*PI()/180)) -> 3037.3411 | Z14: =0.5*1.2*($T14*0.44704)^2*$C$3*$C$5+$C$4*9.81*($C$2*COS(20*PI()/180)+SIN(20*PI()/180)) -> 3921.7019 | AA14: =0.5*1.2*($T14*0.44704)^2*$C$3*$C$5+$C$4*9.81*($C$2*COS(25*PI()/180)+SIN(25*PI()/180)) -> 4777.0324 | AB14: =0.5*1.2*($T14*0.44704)^2*$C$3*$C$5+$C$4*9.81*($C$2*COS(30*PI()/180)+SIN(30*PI()/180)) -> 5596.8231 | AE14: =PI()/30*$H14*$C$6/AD$2*2.23649 -> 12.16303 | AF14: =(0.5*1.2*(AE14*0.44704)^2*$C$3*$C$5+$C$4*9.81*($C$2*COS($C$7*PI()/180)+SIN($C$7*PI()/180)))*$C$6/AD$2 -> 5.9454568 | AG14: =AD$2*$I14/$C$6 -> 4981.7715 | AJ14: =PI()/30*$H14*$C$6/AI$2*2.23649 -> 18.244545 | AK14: =(0.5*1.2*(AJ14*0.44704)^2*$C$3*$C$5+$C$4*9.81*($C$2*COS($C$7*PI()/180)+SIN($C$7*PI()/180)))*$C$6/AI$2 -> 9.6632577 | AL14: =AI$2*$I14/$C$6 -> 3321.181 | AO14: =PI()/30*$H14*$C$6/AN$2*2.23649 -> 27.366817 | AP14: =(0.5*1.2*(AO14*0.44704)^2*$C$3*$C$5+$C$4*9.81*($C$2*COS($C$7*PI()/180)+SIN($C$7*PI()/180)))*$C$6/AN$2 -> 17.009506 | AQ14: =AN$2*$I14/$C$6 -> 2214.1207 | AT14: =PI()/30*$H14*$C$6/AS$2*2.23649 -> 36.48909 | AU14: =(0.5*1.2*(AT14*0.44704)^2*$C$3*$C$5+$C$4*9.81*($C$2*COS($C$7*PI()/180)+SIN($C$7*PI()/180)))*$C$6/AS$2 -> 27.373299 | AV14: =AS$2*$I14/$C$6 -> 1660.5905 | AY14: =PI()/30*$H14*$C$6/AX$2*2.23649 -> 45.611362 | AZ14: =(0.5*1.2*(AY14*0.44704)^2*$C$3*$C$5+$C$4*9.81*($C$2*COS($C$7*PI()/180)+SIN($C$7*PI()/180)))*$C$6/AX$2 -> 41.760483 | BA14: =AX$2*$I14/$C$6 -> 1328.4724
H15: 1700 | I15: 167.4 | K15: =10000/($H15*PI()/30) -> 56.172333 | L15: =20000/($H15*PI()/30) -> 112.34467 | M15: =30000/($H15*PI()/30) -> 168.517 | T15: 39 | U15: =70000/(T15*0.44704) -> 4015.0139 | V15: =0.5*1.2*($T15*0.44704)^2*$C$3*$C$5+$C$4*9.81*($C$2*COS(0*PI()/180)+SIN(0*PI()/180)) -> 296.79784 | W15: =0.5*1.2*($T15*0.44704)^2*$C$3*$C$5+$C$4*9.81*($C$2*COS(5*PI()/180)+SIN(5*PI()/180)) -> 1227.24 | X15: =0.5*1.2*($T15*0.44704)^2*$C$3*$C$5+$C$4*9.81*($C$2*COS(10*PI()/180)+SIN(10*PI()/180)) -> 2149.3002 | Y15: =0.5*1.2*($T15*0.44704)^2*$C$3*$C$5+$C$4*9.81*($C$2*COS(15*PI()/180)+SIN(15*PI()/180)) -> 3055.9607 | Z15: =0.5*1.2*($T15*0.44704)^2*$C$3*$C$5+$C$4*9.81*($C$2*COS(20*PI()/180)+SIN(20*PI()/180)) -> 3940.3215 | AA15: =0.5*1.2*($T15*0.44704)^2*$C$3*$C$5+$C$4*9.81*($C$2*COS(25*PI()/180)+SIN(25*PI()/180)) -> 4795.652 | AB15: =0.5*1.2*($T15*0.44704)^2*$C$3*$C$5+$C$4*9.81*($C$2*COS(30*PI()/180)+SIN(30*PI()/180)) -> 5615.4426 | AE15: =PI()/30*$H15*$C$6/AD$2*2.23649 -> 12.923219 | AF15: =(0.5*1.2*(AE15*0.44704)^2*$C$3*$C$5+$C$4*9.81*($C$2*COS($C$7*PI()/180)+SIN($C$7*PI()/180)))*$C$6/AD$2 -> 5.9966805 | AG15: =AD$2*$I15/$C$6 -> 5157.3813 | AJ15: =PI()/30*$H15*$C$6/AI$2*2.23649 -> 19.384829 | AK15: =(0.5*1.2*(AJ15*0.44704)^2*$C$3*$C$5+$C$4*9.81*($C$2*COS($C$7*PI()/180)+SIN($C$7*PI()/180)))*$C$6/AI$2 -> 9.8361378 | AL15: =AI$2*$I15/$C$6 -> 3438.2542 | AO15: =PI()/30*$H15*$C$6/AN$2*2.23649 -> 29.077244 | AP15: =(0.5*1.2*(AO15*0.44704)^2*$C$3*$C$5+$C$4*9.81*($C$2*COS($C$7*PI()/180)+SIN($C$7*PI()/180)))*$C$6/AN$2 -> 17.592977 | AQ15: =AN$2*$I15/$C$6 -> 2292.1694 | AT15: =PI()/30*$H15*$C$6/AS$2*2.23649 -> 38.769658 | AU15: =(0.5*1.2*(AT15*0.44704)^2*$C$3*$C$5+$C$4*9.81*($C$2*COS($C$7*PI()/180)+SIN($C$7*PI()/180)))*$C$6/AS$2 -> 28.75634 | AV15: =AS$2*$I15/$C$6 -> 1719.1271 | AY15: =PI()/30*$H15*$C$6/AX$2*2.23649 -> 48.462073 | AZ15: =(0.5*1.2*(AY15*0.44704)^2*$C$3*$C$5+$C$4*9.81*($C$2*COS($C$7*PI()/180)+SIN($C$7*PI()/180)))*$C$6/AX$2 -> 44.461735 | BA15: =AX$2*$I15/$C$6 -> 1375.3017
G16: x | H16: 1800 | I16: 170 | K16: =10000/($H16*PI()/30) -> 53.051648 | L16: =20000/($H16*PI()/30) -> 106.1033 | M16: =30000/($H16*PI()/30) -> 159.15494 | T16: 42 | U16: =70000/(T16*0.44704) -> 3728.2272 | V16: =0.5*1.2*($T16*0.44704)^2*$C$3*$C$5+$C$4*9.81*($C$2*COS(0*PI()/180)+SIN(0*PI()/180)) -> 316.907 | W16: =0.5*1.2*($T16*0.44704)^2*$C$3*$C$5+$C$4*9.81*($C$2*COS(5*PI()/180)+SIN(5*PI()/180)) -> 1247.3492 | X16: =0.5*1.2*($T16*0.44704)^2*$C$3*$C$5+$C$4*9.81*($C$2*COS(10*PI()/180)+SIN(10*PI()/180)) -> 2169.4093 | Y16: =0.5*1.2*($T16*0.44704)^2*$C$3*$C$5+$C$4*9.81*($C$2*COS(15*PI()/180)+SIN(15*PI()/180)) -> 3076.0699 | Z16: =0.5*1.2*($T16*0.44704)^2*$C$3*$C$5+$C$4*9.81*($C$2*COS(20*PI()/180)+SIN(20*PI()/180)) -> 3960.4307 | AA16: =0.5*1.2*($T16*0.44704)^2*$C$3*$C$5+$C$4*9.81*($C$2*COS(25*PI()/180)+SIN(25*PI()/180)) -> 4815.7612 | AB16: =0.5*1.2*($T16*0.44704)^2*$C$3*$C$5+$C$4*9.81*($C$2*COS(30*PI()/180)+SIN(30*PI()/180)) -> 5635.5518 | AE16: =PI()/30*$H16*$C$6/AD$2*2.23649 -> 13.683409 | AF16: =(0.5*1.2*(AE16*0.44704)^2*$C$3*$C$5+$C$4*9.81*($C$2*COS($C$7*PI()/180)+SIN($C$7*PI()/180)))*$C$6/AD$2 -> 6.0510087 | AG16: =AD$2*$I16/$C$6 -> 5237.484 | AJ16: =PI()/30*$H16*$C$6/AI$2*2.23649 -> 20.525113 | AK16: =(0.5*1.2*(AJ16*0.44704)^2*$C$3*$C$5+$C$4*9.81*($C$2*COS($C$7*PI()/180)+SIN($C$7*PI()/180)))*$C$6/AI$2 -> 10.019495 | AL16: =AI$2*$I16/$C$6 -> 3491.656 | AO16: =PI()/30*$H16*$C$6/AN$2*2.23649 -> 30.78767 | AP16: =(0.5*1.2*(AO16*0.44704)^2*$C$3*$C$5+$C$4*9.81*($C$2*COS($C$7*PI()/180)+SIN($C$7*PI()/180)))*$C$6/AN$2 -> 18.211809 | AQ16: =AN$2*$I16/$C$6 -> 2327.7706 | AT16: =PI()/30*$H16*$C$6/AS$2*2.23649 -> 41.050226 | AU16: =(0.5*1.2*(AT16*0.44704)^2*$C$3*$C$5+$C$4*9.81*($C$2*COS($C$7*PI()/180)+SIN($C$7*PI()/180)))*$C$6/AS$2 -> 30.223201 | AV16: =AS$2*$I16/$C$6 -> 1745.828 | AY16: =PI()/30*$H16*$C$6/AX$2*2.23649 -> 51.312783 | AZ16: =(0.5*1.2*(AY16*0.44704)^2*$C$3*$C$5+$C$4*9.81*($C$2*COS($C$7*PI()/180)+SIN($C$7*PI()/180)))*$C$6/AX$2 -> 47.326699 | BA16: =AX$2*$I16/$C$6 -> 1396.6624
H17: 1900 | I17: 170 | K17: =10000/($H17*PI()/30) -> 50.259456 | L17: =20000/($H17*PI()/30) -> 100.51891 | M17: =30000/($H17*PI()/30) -> 150.77837 | N17: =40000/($H17*PI()/30) -> 201.03782 | T17: 45 | U17: =70000/(T17*0.44704) -> 3479.6787 | V17: =0.5*1.2*($T17*0.44704)^2*$C$3*$C$5+$C$4*9.81*($C$2*COS(0*PI()/180)+SIN(0*PI()/180)) -> 338.50572 | W17: =0.5*1.2*($T17*0.44704)^2*$C$3*$C$5+$C$4*9.81*($C$2*COS(5*PI()/180)+SIN(5*PI()/180)) -> 1268.9479 | X17: =0.5*1.2*($T17*0.44704)^2*$C$3*$C$5+$C$4*9.81*($C$2*COS(10*PI()/180)+SIN(10*PI()/180)) -> 2191.008 | Y17: =0.5*1.2*($T17*0.44704)^2*$C$3*$C$5+$C$4*9.81*($C$2*COS(15*PI()/180)+SIN(15*PI()/180)) -> 3097.6686 | Z17: =0.5*1.2*($T17*0.44704)^2*$C$3*$C$5+$C$4*9.81*($C$2*COS(20*PI()/180)+SIN(20*PI()/180)) -> 3982.0294 | AA17: =0.5*1.2*($T17*0.44704)^2*$C$3*$C$5+$C$4*9.81*($C$2*COS(25*PI()/180)+SIN(25*PI()/180)) -> 4837.3599 | AB17: =0.5*1.2*($T17*0.44704)^2*$C$3*$C$5+$C$4*9.81*($C$2*COS(30*PI()/180)+SIN(30*PI()/180)) -> 5657.1505 | AE17: =PI()/30*$H17*$C$6/AD$2*2.23649 -> 14.443598 | AF17: =(0.5*1.2*(AE17*0.44704)^2*$C$3*$C$5+$C$4*9.81*($C$2*COS($C$7*PI()/180)+SIN($C$7*PI()/180)))*$C$6/AD$2 -> 6.1084414 | AG17: =AD$2*$I17/$C$6 -> 5237.484 | AJ17: =PI()/30*$H17*$C$6/AI$2*2.23649 -> 21.665397 | AK17: =(0.5*1.2*(AJ17*0.44704)^2*$C$3*$C$5+$C$4*9.81*($C$2*COS($C$7*PI()/180)+SIN($C$7*PI()/180)))*$C$6/AI$2 -> 10.213331 | AL17: =AI$2*$I17/$C$6 -> 3491.656 | AO17: =PI()/30*$H17*$C$6/AN$2*2.23649 -> 32.498096 | AP17: =(0.5*1.2*(AO17*0.44704)^2*$C$3*$C$5+$C$4*9.81*($C$2*COS($C$7*PI()/180)+SIN($C$7*PI()/180)))*$C$6/AN$2 -> 18.866003 | AQ17: =AN$2*$I17/$C$6 -> 2327.7706 | AT17: =PI()/30*$H17*$C$6/AS$2*2.23649 -> 43.330794 | AU17: =(0.5*1.2*(AT17*0.44704)^2*$C$3*$C$5+$C$4*9.81*($C$2*COS($C$7*PI()/180)+SIN($C$7*PI()/180)))*$C$6/AS$2 -> 31.773883 | AV17: =AS$2*$I17/$C$6 -> 1745.828 | AY17: =PI()/30*$H17*$C$6/AX$2*2.23649 -> 54.163493 | AZ17: =(0.5*1.2*(AY17*0.44704)^2*$C$3*$C$5+$C$4*9.81*($C$2*COS($C$7*PI()/180)+SIN($C$7*PI()/180)))*$C$6/AX$2 -> 50.355375 | BA17: =AX$2*$I17/$C$6 -> 1396.6624
H18: 2000 | I18: 170 | K18: =10000/($H18*PI()/30) -> 47.746483 | L18: =20000/($H18*PI()/30) -> 95.492966 | M18: =30000/($H18*PI()/30) -> 143.23945 | N18: =40000/($H18*PI()/30) -> 190.98593 | T18: 48 | U18: =70000/(T18*0.44704) -> 3262.1988 | V18: =0.5*1.2*($T18*0.44704)^2*$C$3*$C$5+$C$4*9.81*($C$2*COS(0*PI()/180)+SIN(0*PI()/180)) -> 361.594 | W18: =0.5*1.2*($T18*0.44704)^2*$C$3*$C$5+$C$4*9.81*($C$2*COS(5*PI()/180)+SIN(5*PI()/180)) -> 1292.0362 | X18: =0.5*1.2*($T18*0.44704)^2*$C$3*$C$5+$C$4*9.81*($C$2*COS(10*PI()/180)+SIN(10*PI()/180)) -> 2214.0963 | Y18: =0.5*1.2*($T18*0.44704)^2*$C$3*$C$5+$C$4*9.81*($C$2*COS(15*PI()/180)+SIN(15*PI()/180)) -> 3120.7569 | Z18: =0.5*1.2*($T18*0.44704)^2*$C$3*$C$5+$C$4*9.81*($C$2*COS(20*PI()/180)+SIN(20*PI()/180)) -> 4005.1177 | AA18: =0.5*1.2*($T18*0.44704)^2*$C$3*$C$5+$C$4*9.81*($C$2*COS(25*PI()/180)+SIN(25*PI()/180)) -> 4860.4482 | AB18: =0.5*1.2*($T18*0.44704)^2*$C$3*$C$5+$C$4*9.81*($C$2*COS(30*PI()/180)+SIN(30*PI()/180)) -> 5680.2388 | AE18: =PI()/30*$H18*$C$6/AD$2*2.23649 -> 15.203787 | AF18: =(0.5*1.2*(AE18*0.44704)^2*$C$3*$C$5+$C$4*9.81*($C$2*COS($C$7*PI()/180)+SIN($C$7*PI()/180)))*$C$6/AD$2 -> 6.1689785 | AG18: =AD$2*$I18/$C$6 -> 5237.484 | AJ18: =PI()/30*$H18*$C$6/AI$2*2.23649 -> 22.805681 | AK18: =(0.5*1.2*(AJ18*0.44704)^2*$C$3*$C$5+$C$4*9.81*($C$2*COS($C$7*PI()/180)+SIN($C$7*PI()/180)))*$C$6/AI$2 -> 10.417644 | AL18: =AI$2*$I18/$C$6 -> 3491.656 | AO18: =PI()/30*$H18*$C$6/AN$2*2.23649 -> 34.208522 | AP18: =(0.5*1.2*(AO18*0.44704)^2*$C$3*$C$5+$C$4*9.81*($C$2*COS($C$7*PI()/180)+SIN($C$7*PI()/180)))*$C$6/AN$2 -> 19.555559 | AQ18: =AN$2*$I18/$C$6 -> 2327.7706 | AT18: =PI()/30*$H18*$C$6/AS$2*2.23649 -> 45.611362 | AU18: =(0.5*1.2*(AT18*0.44704)^2*$C$3*$C$5+$C$4*9.81*($C$2*COS($C$7*PI()/180)+SIN($C$7*PI()/180)))*$C$6/AS$2 -> 33.408386 | AV18: =AS$2*$I18/$C$6 -> 1745.828 | AY18: =PI()/30*$H18*$C$6/AX$2*2.23649 -> 57.014203 | AZ18: =(0.5*1.2*(AY18*0.44704)^2*$C$3*$C$5+$C$4*9.81*($C$2*COS($C$7*PI()/180)+SIN($C$7*PI()/180)))*$C$6/AX$2 -> 53.547763 | BA18: =AX$2*$I18/$C$6 -> 1396.6624
H19: 2100 | I19: 170 | K19: =10000/($H19*PI()/30) -> 45.472841 | L19: =20000/($H19*PI()/30) -> 90.945682 | M19: =30000/($H19*PI()/30) -> 136.41852 | N19: =40000/($H19*PI()/30) -> 181.89136 | T19: 51 | U19: =70000/(T19*0.44704) -> 3070.3047 | V19: =0.5*1.2*($T19*0.44704)^2*$C$3*$C$5+$C$4*9.81*($C$2*COS(0*PI()/180)+SIN(0*PI()/180)) -> 386.17186 | W19: =0.5*1.2*($T19*0.44704)^2*$C$3*$C$5+$C$4*9.81*($C$2*COS(5*PI()/180)+SIN(5*PI()/180)) -> 1316.6141 | X19: =0.5*1.2*($T19*0.44704)^2*$C$3*$C$5+$C$4*9.81*($C$2*COS(10*PI()/180)+SIN(10*PI()/180)) -> 2238.6742 | Y19: =0.5*1.2*($T19*0.44704)^2*$C$3*$C$5+$C$4*9.81*($C$2*COS(15*PI()/180)+SIN(15*PI()/180)) -> 3145.3347 | Z19: =0.5*1.2*($T19*0.44704)^2*$C$3*$C$5+$C$4*9.81*($C$2*COS(20*PI()/180)+SIN(20*PI()/180)) -> 4029.6955 | AA19: =0.5*1.2*($T19*0.44704)^2*$C$3*$C$5+$C$4*9.81*($C$2*COS(25*PI()/180)+SIN(25*PI()/180)) -> 4885.026 | AB19: =0.5*1.2*($T19*0.44704)^2*$C$3*$C$5+$C$4*9.81*($C$2*COS(30*PI()/180)+SIN(30*PI()/180)) -> 5704.8167 | AE19: =PI()/30*$H19*$C$6/AD$2*2.23649 -> 15.963977 | AF19: =(0.5*1.2*(AE19*0.44704)^2*$C$3*$C$5+$C$4*9.81*($C$2*COS($C$7*PI()/180)+SIN($C$7*PI()/180)))*$C$6/AD$2 -> 6.2326201 | AG19: =AD$2*$I19/$C$6 -> 5237.484 | AJ19: =PI()/30*$H19*$C$6/AI$2*2.23649 -> 23.945965 | AK19: =(0.5*1.2*(AJ19*0.44704)^2*$C$3*$C$5+$C$4*9.81*($C$2*COS($C$7*PI()/180)+SIN($C$7*PI()/180)))*$C$6/AI$2 -> 10.632434 | AL19: =AI$2*$I19/$C$6 -> 3491.656 | AO19: =PI()/30*$H19*$C$6/AN$2*2.23649 -> 35.918948 | AP19: =(0.5*1.2*(AO19*0.44704)^2*$C$3*$C$5+$C$4*9.81*($C$2*COS($C$7*PI()/180)+SIN($C$7*PI()/180)))*$C$6/AN$2 -> 20.280477 | AQ19: =AN$2*$I19/$C$6 -> 2327.7706 | AT19: =PI()/30*$H19*$C$6/AS$2*2.23649 -> 47.891931 | AU19: =(0.5*1.2*(AT19*0.44704)^2*$C$3*$C$5+$C$4*9.81*($C$2*COS($C$7*PI()/180)+SIN($C$7*PI()/180)))*$C$6/AS$2 -> 35.12671 | AV19: =AS$2*$I19/$C$6 -> 1745.828 | AY19: =PI()/30*$H19*$C$6/AX$2*2.23649 -> 59.864913 | AZ19: =(0.5*1.2*(AY19*0.44704)^2*$C$3*$C$5+$C$4*9.81*($C$2*COS($C$7*PI()/180)+SIN($C$7*PI()/180)))*$C$6/AX$2 -> 56.903864 | BA19: =AX$2*$I19/$C$6 -> 1396.6624
H20: 2200 | I20: 170 | K20: =10000/($H20*PI()/30) -> 43.405894 | L20: =20000/($H20*PI()/30) -> 86.811787 | M20: =30000/($H20*PI()/30) -> 130.21768 | N20: =40000/($H20*PI()/30) -> 173.62357 | T20: 54 | U20: =70000/(T20*0.44704) -> 2899.7322 | V20: =0.5*1.2*($T20*0.44704)^2*$C$3*$C$5+$C$4*9.81*($C$2*COS(0*PI()/180)+SIN(0*PI()/180)) -> 412.23928 | W20: =0.5*1.2*($T20*0.44704)^2*$C$3*$C$5+$C$4*9.81*($C$2*COS(5*PI()/180)+SIN(5*PI()/180)) -> 1342.6815 | X20: =0.5*1.2*($T20*0.44704)^2*$C$3*$C$5+$C$4*9.81*($C$2*COS(10*PI()/180)+SIN(10*PI()/180)) -> 2264.7416 | Y20: =0.5*1.2*($T20*0.44704)^2*$C$3*$C$5+$C$4*9.81*($C$2*COS(15*PI()/180)+SIN(15*PI()/180)) -> 3171.4022 | Z20: =0.5*1.2*($T20*0.44704)^2*$C$3*$C$5+$C$4*9.81*($C$2*COS(20*PI()/180)+SIN(20*PI()/180)) -> 4055.7629 | AA20: =0.5*1.2*($T20*0.44704)^2*$C$3*$C$5+$C$4*9.81*($C$2*COS(25*PI()/180)+SIN(25*PI()/180)) -> 4911.0934 | AB20: =0.5*1.2*($T20*0.44704)^2*$C$3*$C$5+$C$4*9.81*($C$2*COS(30*PI()/180)+SIN(30*PI()/180)) -> 5730.8841 | AE20: =PI()/30*$H20*$C$6/AD$2*2.23649 -> 16.724166 | AF20: =(0.5*1.2*(AE20*0.44704)^2*$C$3*$C$5+$C$4*9.81*($C$2*COS($C$7*PI()/180)+SIN($C$7*PI()/180)))*$C$6/AD$2 -> 6.2993662 | AG20: =AD$2*$I20/$C$6 -> 5237.484 | AJ20: =PI()/30*$H20*$C$6/AI$2*2.23649 -> 25.086249 | AK20: =(0.5*1.2*(AJ20*0.44704)^2*$C$3*$C$5+$C$4*9.81*($C$2*COS($C$7*PI()/180)+SIN($C$7*PI()/180)))*$C$6/AI$2 -> 10.857702 | AL20: =AI$2*$I20/$C$6 -> 3491.656 | AO20: =PI()/30*$H20*$C$6/AN$2*2.23649 -> 37.629374 | AP20: =(0.5*1.2*(AO20*0.44704)^2*$C$3*$C$5+$C$4*9.81*($C$2*COS($C$7*PI()/180)+SIN($C$7*PI()/180)))*$C$6/AN$2 -> 21.040756 | AQ20: =AN$2*$I20/$C$6 -> 2327.7706 | AT20: =PI()/30*$H20*$C$6/AS$2*2.23649 -> 50.172499 | AU20: =(0.5*1.2*(AT20*0.44704)^2*$C$3*$C$5+$C$4*9.81*($C$2*COS($C$7*PI()/180)+SIN($C$7*PI()/180)))*$C$6/AS$2 -> 36.928854 | AV20: =AS$2*$I20/$C$6 -> 1745.828 | AY20: =PI()/30*$H20*$C$6/AX$2*2.23649 -> 62.715623 | AZ20: =(0.5*1.2*(AY20*0.44704)^2*$C$3*$C$5+$C$4*9.81*($C$2*COS($C$7*PI()/180)+SIN($C$7*PI()/180)))*$C$6/AX$2 -> 60.423677 | BA20: =AX$2*$I20/$C$6 -> 1396.6624
H21: 2300 | I21: 170 | K21: =10000/($H21*PI()/30) -> 41.518681 | L21: =20000/($H21*PI()/30) -> 83.037362 | M21: =30000/($H21*PI()/30) -> 124.55604 | N21: =40000/($H21*PI()/30) -> 166.07472 | O21: =50000/($H21*PI()/30) -> 207.5934 | T21: 57 | U21: =70000/(T21*0.44704) -> 2747.1147 | V21: =0.5*1.2*($T21*0.44704)^2*$C$3*$C$5+$C$4*9.81*($C$2*COS(0*PI()/180)+SIN(0*PI()/180)) -> 439.79627 | W21: =0.5*1.2*($T21*0.44704)^2*$C$3*$C$5+$C$4*9.81*($C$2*COS(5*PI()/180)+SIN(5*PI()/180)) -> 1370.2385 | X21: =0.5*1.2*($T21*0.44704)^2*$C$3*$C$5+$C$4*9.81*($C$2*COS(10*PI()/180)+SIN(10*PI()/180)) -> 2292.2986 | Y21: =0.5*1.2*($T21*0.44704)^2*$C$3*$C$5+$C$4*9.81*($C$2*COS(15*PI()/180)+SIN(15*PI()/180)) -> 3198.9591 | Z21: =0.5*1.2*($T21*0.44704)^2*$C$3*$C$5+$C$4*9.81*($C$2*COS(20*PI()/180)+SIN(20*PI()/180)) -> 4083.3199 | AA21: =0.5*1.2*($T21*0.44704)^2*$C$3*$C$5+$C$4*9.81*($C$2*COS(25*PI()/180)+SIN(25*PI()/180)) -> 4938.6504 | AB21: =0.5*1.2*($T21*0.44704)^2*$C$3*$C$5+$C$4*9.81*($C$2*COS(30*PI()/180)+SIN(30*PI()/180)) -> 5758.4411 | AE21: =PI()/30*$H21*$C$6/AD$2*2.23649 -> 17.484356 | AF21: =(0.5*1.2*(AE21*0.44704)^2*$C$3*$C$5+$C$4*9.81*($C$2*COS($C$7*PI()/180)+SIN($C$7*PI()/180)))*$C$6/AD$2 -> 6.3692168 | AG21: =AD$2*$I21/$C$6 -> 5237.484 | AJ21: =PI()/30*$H21*$C$6/AI$2*2.23649 -> 26.226533 | AK21: =(0.5*1.2*(AJ21*0.44704)^2*$C$3*$C$5+$C$4*9.81*($C$2*COS($C$7*PI()/180)+SIN($C$7*PI()/180)))*$C$6/AI$2 -> 11.093448 | AL21: =AI$2*$I21/$C$6 -> 3491.656 | AO21: =PI()/30*$H21*$C$6/AN$2*2.23649 -> 39.3398 | AP21: =(0.5*1.2*(AO21*0.44704)^2*$C$3*$C$5+$C$4*9.81*($C$2*COS($C$7*PI()/180)+SIN($C$7*PI()/180)))*$C$6/AN$2 -> 21.836398 | AQ21: =AN$2*$I21/$C$6 -> 2327.7706 | AT21: =PI()/30*$H21*$C$6/AS$2*2.23649 -> 52.453067 | AU21: =(0.5*1.2*(AT21*0.44704)^2*$C$3*$C$5+$C$4*9.81*($C$2*COS($C$7*PI()/180)+SIN($C$7*PI()/180)))*$C$6/AS$2 -> 38.814819 | AV21: =AS$2*$I21/$C$6 -> 1745.828 | AY21: =PI()/30*$H21*$C$6/AX$2*2.23649 -> 65.566333 | AZ21: =(0.5*1.2*(AY21*0.44704)^2*$C$3*$C$5+$C$4*9.81*($C$2*COS($C$7*PI()/180)+SIN($C$7*PI()/180)))*$C$6/AX$2 -> 64.107202 | BA21: =AX$2*$I21/$C$6 -> 1396.6624
H22: 2400 | I22: 170 | K22: =10000/($H22*PI()/30) -> 39.788736 | L22: =20000/($H22*PI()/30) -> 79.577472 | M22: =30000/($H22*PI()/30) -> 119.36621 | N22: =40000/($H22*PI()/30) -> 159.15494 | O22: =50000/($H22*PI()/30) -> 198.94368 | T22: 60 | U22: =70000/(T22*0.44704) -> 2609.759 | V22: =0.5*1.2*($T22*0.44704)^2*$C$3*$C$5+$C$4*9.81*($C$2*COS(0*PI()/180)+SIN(0*PI()/180)) -> 468.84282 | W22: =0.5*1.2*($T22*0.44704)^2*$C$3*$C$5+$C$4*9.81*($C$2*COS(5*PI()/180)+SIN(5*PI()/180)) -> 1399.285 | X22: =0.5*1.2*($T22*0.44704)^2*$C$3*$C$5+$C$4*9.81*($C$2*COS(10*PI()/180)+SIN(10*PI()/180)) -> 2321.3451 | Y22: =0.5*1.2*($T22*0.44704)^2*$C$3*$C$5+$C$4*9.81*($C$2*COS(15*PI()/180)+SIN(15*PI()/180)) -> 3228.0057 | Z22: =0.5*1.2*($T22*0.44704)^2*$C$3*$C$5+$C$4*9.81*($C$2*COS(20*PI()/180)+SIN(20*PI()/180)) -> 4112.3665 | AA22: =0.5*1.2*($T22*0.44704)^2*$C$3*$C$5+$C$4*9.81*($C$2*COS(25*PI()/180)+SIN(25*PI()/180)) -> 4967.697 | AB22: =0.5*1.2*($T22*0.44704)^2*$C$3*$C$5+$C$4*9.81*($C$2*COS(30*PI()/180)+SIN(30*PI()/180)) -> 5787.4876 | AE22: =PI()/30*$H22*$C$6/AD$2*2.23649 -> 18.244545 | AF22: =(0.5*1.2*(AE22*0.44704)^2*$C$3*$C$5+$C$4*9.81*($C$2*COS($C$7*PI()/180)+SIN($C$7*PI()/180)))*$C$6/AD$2 -> 6.4421718 | AG22: =AD$2*$I22/$C$6 -> 5237.484 | AJ22: =PI()/30*$H22*$C$6/AI$2*2.23649 -> 27.366817 | AK22: =(0.5*1.2*(AJ22*0.44704)^2*$C$3*$C$5+$C$4*9.81*($C$2*COS($C$7*PI()/180)+SIN($C$7*PI()/180)))*$C$6/AI$2 -> 11.339671 | AL22: =AI$2*$I22/$C$6 -> 3491.656 | AO22: =PI()/30*$H22*$C$6/AN$2*2.23649 -> 41.050226 | AP22: =(0.5*1.2*(AO22*0.44704)^2*$C$3*$C$5+$C$4*9.81*($C$2*COS($C$7*PI()/180)+SIN($C$7*PI()/180)))*$C$6/AN$2 -> 22.667401 | AQ22: =AN$2*$I22/$C$6 -> 2327.7706 | AT22: =PI()/30*$H22*$C$6/AS$2*2.23649 -> 54.733635 | AU22: =(0.5*1.2*(AT22*0.44704)^2*$C$3*$C$5+$C$4*9.81*($C$2*COS($C$7*PI()/180)+SIN($C$7*PI()/180)))*$C$6/AS$2 -> 40.784604 | AV22: =AS$2*$I22/$C$6 -> 1745.828 | AY22: =PI()/30*$H22*$C$6/AX$2*2.23649 -> 68.417044 | AZ22: =(0.5*1.2*(AY22*0.44704)^2*$C$3*$C$5+$C$4*9.81*($C$2*COS($C$7*PI()/180)+SIN($C$7*PI()/180)))*$C$6/AX$2 -> 67.954439 | BA22: =AX$2*$I22/$C$6 -> 1396.6624
H23: 2500 | I23: 170 | K23: =10000/($H23*PI()/30) -> 38.197186 | L23: =20000/($H23*PI()/30) -> 76.394373 | M23: =30000/($H23*PI()/30) -> 114.59156 | N23: =40000/($H23*PI()/30) -> 152.78875 | O23: =50000/($H23*PI()/30) -> 190.98593 | T23: 63 | U23: =70000/(T23*0.44704) -> 2485.4848 | V23: =0.5*1.2*($T23*0.44704)^2*$C$3*$C$5+$C$4*9.81*($C$2*COS(0*PI()/180)+SIN(0*PI()/180)) -> 499.37894 | W23: =0.5*1.2*($T23*0.44704)^2*$C$3*$C$5+$C$4*9.81*($C$2*COS(5*PI()/180)+SIN(5*PI()/180)) -> 1429.8211 | X23: =0.5*1.2*($T23*0.44704)^2*$C$3*$C$5+$C$4*9.81*($C$2*COS(10*PI()/180)+SIN(10*PI()/180)) -> 2351.8813 | Y23: =0.5*1.2*($T23*0.44704)^2*$C$3*$C$5+$C$4*9.81*($C$2*COS(15*PI()/180)+SIN(15*PI()/180)) -> 3258.5418 | Z23: =0.5*1.2*($T23*0.44704)^2*$C$3*$C$5+$C$4*9.81*($C$2*COS(20*PI()/180)+SIN(20*PI()/180)) -> 4142.9026 | AA23: =0.5*1.2*($T23*0.44704)^2*$C$3*$C$5+$C$4*9.81*($C$2*COS(25*PI()/180)+SIN(25*PI()/180)) -> 4998.2331 | AB23: =0.5*1.2*($T23*0.44704)^2*$C$3*$C$5+$C$4*9.81*($C$2*COS(30*PI()/180)+SIN(30*PI()/180)) -> 5818.0237 | AE23: =PI()/30*$H23*$C$6/AD$2*2.23649 -> 19.004734 | AF23: =(0.5*1.2*(AE23*0.44704)^2*$C$3*$C$5+$C$4*9.81*($C$2*COS($C$7*PI()/180)+SIN($C$7*PI()/180)))*$C$6/AD$2 -> 6.5182313 | AG23: =AD$2*$I23/$C$6 -> 5237.484 | AJ23: =PI()/30*$H23*$C$6/AI$2*2.23649 -> 28.507102 | AK23: =(0.5*1.2*(AJ23*0.44704)^2*$C$3*$C$5+$C$4*9.81*($C$2*COS($C$7*PI()/180)+SIN($C$7*PI()/180)))*$C$6/AI$2 -> 11.596372 | AL23: =AI$2*$I23/$C$6 -> 3491.656 | AO23: =PI()/30*$H23*$C$6/AN$2*2.23649 -> 42.760652 | AP23: =(0.5*1.2*(AO23*0.44704)^2*$C$3*$C$5+$C$4*9.81*($C$2*COS($C$7*PI()/180)+SIN($C$7*PI()/180)))*$C$6/AN$2 -> 23.533766 | AQ23: =AN$2*$I23/$C$6 -> 2327.7706 | AT23: =PI()/30*$H23*$C$6/AS$2*2.23649 -> 57.014203 | AU23: =(0.5*1.2*(AT23*0.44704)^2*$C$3*$C$5+$C$4*9.81*($C$2*COS($C$7*PI()/180)+SIN($C$7*PI()/180)))*$C$6/AS$2 -> 42.83821 | AV23: =AS$2*$I23/$C$6 -> 1745.828 | AY23: =PI()/30*$H23*$C$6/AX$2*2.23649 -> 71.267754 | AZ23: =(0.5*1.2*(AY23*0.44704)^2*$C$3*$C$5+$C$4*9.81*($C$2*COS($C$7*PI()/180)+SIN($C$7*PI()/180)))*$C$6/AX$2 -> 71.965389 | BA23: =AX$2*$I23/$C$6 -> 1396.6624
H24: 2600 | I24: 170 | K24: =10000/($H24*PI()/30) -> 36.728064 | L24: =20000/($H24*PI()/30) -> 73.456128 | M24: =30000/($H24*PI()/30) -> 110.18419 | N24: =40000/($H24*PI()/30) -> 146.91226 | O24: =50000/($H24*PI()/30) -> 183.64032 | T24: 66 | U24: =70000/(T24*0.44704) -> 2372.5082 | V24: =0.5*1.2*($T24*0.44704)^2*$C$3*$C$5+$C$4*9.81*($C$2*COS(0*PI()/180)+SIN(0*PI()/180)) -> 531.40463 | W24: =0.5*1.2*($T24*0.44704)^2*$C$3*$C$5+$C$4*9.81*($C$2*COS(5*PI()/180)+SIN(5*PI()/180)) -> 1461.8468 | X24: =0.5*1.2*($T24*0.44704)^2*$C$3*$C$5+$C$4*9.81*($C$2*COS(10*PI()/180)+SIN(10*PI()/180)) -> 2383.9069 | Y24: =0.5*1.2*($T24*0.44704)^2*$C$3*$C$5+$C$4*9.81*($C$2*COS(15*PI()/180)+SIN(15*PI()/180)) -> 3290.5675 | Z24: =0.5*1.2*($T24*0.44704)^2*$C$3*$C$5+$C$4*9.81*($C$2*COS(20*PI()/180)+SIN(20*PI()/180)) -> 4174.9283 | AA24: =0.5*1.2*($T24*0.44704)^2*$C$3*$C$5+$C$4*9.81*($C$2*COS(25*PI()/180)+SIN(25*PI()/180)) -> 5030.2588 | AB24: =0.5*1.2*($T24*0.44704)^2*$C$3*$C$5+$C$4*9.81*($C$2*COS(30*PI()/180)+SIN(30*PI()/180)) -> 5850.0494 | AE24: =PI()/30*$H24*$C$6/AD$2*2.23649 -> 19.764924 | AF24: =(0.5*1.2*(AE24*0.44704)^2*$C$3*$C$5+$C$4*9.81*($C$2*COS($C$7*PI()/180)+SIN($C$7*PI()/180)))*$C$6/AD$2 -> 6.5973952 | AG24: =AD$2*$I24/$C$6 -> 5237.484 | AJ24: =PI()/30*$H24*$C$6/AI$2*2.23649 -> 29.647386 | AK24: =(0.5*1.2*(AJ24*0.44704)^2*$C$3*$C$5+$C$4*9.81*($C$2*COS($C$7*PI()/180)+SIN($C$7*PI()/180)))*$C$6/AI$2 -> 11.86355 | AL24: =AI$2*$I24/$C$6 -> 3491.656 | AO24: =PI()/30*$H24*$C$6/AN$2*2.23649 -> 44.471078 | AP24: =(0.5*1.2*(AO24*0.44704)^2*$C$3*$C$5+$C$4*9.81*($C$2*COS($C$7*PI()/180)+SIN($C$7*PI()/180)))*$C$6/AN$2 -> 24.435493 | AQ24: =AN$2*$I24/$C$6 -> 2327.7706 | AT24: =PI()/30*$H24*$C$6/AS$2*2.23649 -> 59.294771 | AU24: =(0.5*1.2*(AT24*0.44704)^2*$C$3*$C$5+$C$4*9.81*($C$2*COS($C$7*PI()/180)+SIN($C$7*PI()/180)))*$C$6/AS$2 -> 44.975637 | AV24: =AS$2*$I24/$C$6 -> 1745.828 | AY24: =PI()/30*$H24*$C$6/AX$2*2.23649 -> 74.118464 | AZ24: =(0.5*1.2*(AY24*0.44704)^2*$C$3*$C$5+$C$4*9.81*($C$2*COS($C$7*PI()/180)+SIN($C$7*PI()/180)))*$C$6/AX$2 -> 76.14005 | BA24: =AX$2*$I24/$C$6 -> 1396.6624
H25: 2700 | I25: 170 | K25: =10000/($H25*PI()/30) -> 35.367765 | L25: =20000/($H25*PI()/30) -> 70.73553 | M25: =30000/($H25*PI()/30) -> 106.1033 | N25: =40000/($H25*PI()/30) -> 141.47106 | O25: =50000/($H25*PI()/30) -> 176.83883 | T25: 69 | U25: =70000/(T25*0.44704) -> 2269.3557 | V25: =0.5*1.2*($T25*0.44704)^2*$C$3*$C$5+$C$4*9.81*($C$2*COS(0*PI()/180)+SIN(0*PI()/180)) -> 564.91989 | W25: =0.5*1.2*($T25*0.44704)^2*$C$3*$C$5+$C$4*9.81*($C$2*COS(5*PI()/180)+SIN(5*PI()/180)) -> 1495.3621 | X25: =0.5*1.2*($T25*0.44704)^2*$C$3*$C$5+$C$4*9.81*($C$2*COS(10*PI()/180)+SIN(10*PI()/180)) -> 2417.4222 | Y25: =0.5*1.2*($T25*0.44704)^2*$C$3*$C$5+$C$4*9.81*($C$2*COS(15*PI()/180)+SIN(15*PI()/180)) -> 3324.0828 | Z25: =0.5*1.2*($T25*0.44704)^2*$C$3*$C$5+$C$4*9.81*($C$2*COS(20*PI()/180)+SIN(20*PI()/180)) -> 4208.4436 | AA25: =0.5*1.2*($T25*0.44704)^2*$C$3*$C$5+$C$4*9.81*($C$2*COS(25*PI()/180)+SIN(25*PI()/180)) -> 5063.7741 | AB25: =0.5*1.2*($T25*0.44704)^2*$C$3*$C$5+$C$4*9.81*($C$2*COS(30*PI()/180)+SIN(30*PI()/180)) -> 5883.5647 | AE25: =PI()/30*$H25*$C$6/AD$2*2.23649 -> 20.525113 | AF25: =(0.5*1.2*(AE25*0.44704)^2*$C$3*$C$5+$C$4*9.81*($C$2*COS($C$7*PI()/180)+SIN($C$7*PI()/180)))*$C$6/AD$2 -> 6.6796637 | AG25: =AD$2*$I25/$C$6 -> 5237.484 | AJ25: =PI()/30*$H25*$C$6/AI$2*2.23649 -> 30.78767 | AK25: =(0.5*1.2*(AJ25*0.44704)^2*$C$3*$C$5+$C$4*9.81*($C$2*COS($C$7*PI()/180)+SIN($C$7*PI()/180)))*$C$6/AI$2 -> 12.141206 | AL25: =AI$2*$I25/$C$6 -> 3491.656 | AO25: =PI()/30*$H25*$C$6/AN$2*2.23649 -> 46.181504 | AP25: =(0.5*1.2*(AO25*0.44704)^2*$C$3*$C$5+$C$4*9.81*($C$2*COS($C$7*PI()/180)+SIN($C$7*PI()/180)))*$C$6/AN$2 -> 25.372582 | AQ25: =AN$2*$I25/$C$6 -> 2327.7706 | AT25: =PI()/30*$H25*$C$6/AS$2*2.23649 -> 61.575339 | AU25: =(0.5*1.2*(AT25*0.44704)^2*$C$3*$C$5+$C$4*9.81*($C$2*COS($C$7*PI()/180)+SIN($C$7*PI()/180)))*$C$6/AS$2 -> 47.196885 | AV25: =AS$2*$I25/$C$6 -> 1745.828 | AY25: =PI()/30*$H25*$C$6/AX$2*2.23649 -> 76.969174 | AZ25: =(0.5*1.2*(AY25*0.44704)^2*$C$3*$C$5+$C$4*9.81*($C$2*COS($C$7*PI()/180)+SIN($C$7*PI()/180)))*$C$6/AX$2 -> 80.478424 | BA25: =AX$2*$I25/$C$6 -> 1396.6624
H26: 2800 | I26: 170 | K26: =10000/($H26*PI()/30) -> 34.104631 | L26: =20000/($H26*PI()/30) -> 68.209261 | M26: =30000/($H26*PI()/30) -> 102.31389 | N26: =40000/($H26*PI()/30) -> 136.41852 | O26: =50000/($H26*PI()/30) -> 170.52315 | P26: =60000/($H26*PI()/30) -> 204.62778 | T26: 72 | U26: =70000/(T26*0.44704) -> 2174.7992 | V26: =0.5*1.2*($T26*0.44704)^2*$C$3*$C$5+$C$4*9.81*($C$2*COS(0*PI()/180)+SIN(0*PI()/180)) -> 599.92471 | W26: =0.5*1.2*($T26*0.44704)^2*$C$3*$C$5+$C$4*9.81*($C$2*COS(5*PI()/180)+SIN(5*PI()/180)) -> 1530.3669 | X26: =0.5*1.2*($T26*0.44704)^2*$C$3*$C$5+$C$4*9.81*($C$2*COS(10*PI()/180)+SIN(10*PI()/180)) -> 2452.427 | Y26: =0.5*1.2*($T26*0.44704)^2*$C$3*$C$5+$C$4*9.81*($C$2*COS(15*PI()/180)+SIN(15*PI()/180)) -> 3359.0876 | Z26: =0.5*1.2*($T26*0.44704)^2*$C$3*$C$5+$C$4*9.81*($C$2*COS(20*PI()/180)+SIN(20*PI()/180)) -> 4243.4484 | AA26: =0.5*1.2*($T26*0.44704)^2*$C$3*$C$5+$C$4*9.81*($C$2*COS(25*PI()/180)+SIN(25*PI()/180)) -> 5098.7789 | AB26: =0.5*1.2*($T26*0.44704)^2*$C$3*$C$5+$C$4*9.81*($C$2*COS(30*PI()/180)+SIN(30*PI()/180)) -> 5918.5695 | AE26: =PI()/30*$H26*$C$6/AD$2*2.23649 -> 21.285302 | AF26: =(0.5*1.2*(AE26*0.44704)^2*$C$3*$C$5+$C$4*9.81*($C$2*COS($C$7*PI()/180)+SIN($C$7*PI()/180)))*$C$6/AD$2 -> 6.7650365 | AG26: =AD$2*$I26/$C$6 -> 5237.484 | AJ26: =PI()/30*$H26*$C$6/AI$2*2.23649 -> 31.927954 | AK26: =(0.5*1.2*(AJ26*0.44704)^2*$C$3*$C$5+$C$4*9.81*($C$2*COS($C$7*PI()/180)+SIN($C$7*PI()/180)))*$C$6/AI$2 -> 12.429339 | AL26: =AI$2*$I26/$C$6 -> 3491.656 | AO26: =PI()/30*$H26*$C$6/AN$2*2.23649 -> 47.891931 | AP26: =(0.5*1.2*(AO26*0.44704)^2*$C$3*$C$5+$C$4*9.81*($C$2*COS($C$7*PI()/180)+SIN($C$7*PI()/180)))*$C$6/AN$2 -> 26.345032 | AQ26: =AN$2*$I26/$C$6 -> 2327.7706 | AT26: =PI()/30*$H26*$C$6/AS$2*2.23649 -> 63.855907 | AU26: =(0.5*1.2*(AT26*0.44704)^2*$C$3*$C$5+$C$4*9.81*($C$2*COS($C$7*PI()/180)+SIN($C$7*PI()/180)))*$C$6/AS$2 -> 49.501953 | AV26: =AS$2*$I26/$C$6 -> 1745.828 | AY26: =PI()/30*$H26*$C$6/AX$2*2.23649 -> 79.819884 | AZ26: =(0.5*1.2*(AY26*0.44704)^2*$C$3*$C$5+$C$4*9.81*($C$2*COS($C$7*PI()/180)+SIN($C$7*PI()/180)))*$C$6/AX$2 -> 84.980511 | BA26: =AX$2*$I26/$C$6 -> 1396.6624
H27: 2900 | I27: 170 | K27: =10000/($H27*PI()/30) -> 32.928609 | L27: =20000/($H27*PI()/30) -> 65.857218 | M27: =30000/($H27*PI()/30) -> 98.785827 | N27: =40000/($H27*PI()/30) -> 131.71444 | O27: =50000/($H27*PI()/30) -> 164.64304 | P27: =60000/($H27*PI()/30) -> 197.57165 | T27: 75 | U27: =70000/(T27*0.44704) -> 2087.8072 | V27: =0.5*1.2*($T27*0.44704)^2*$C$3*$C$5+$C$4*9.81*($C$2*COS(0*PI()/180)+SIN(0*PI()/180)) -> 636.4191 | W27: =0.5*1.2*($T27*0.44704)^2*$C$3*$C$5+$C$4*9.81*($C$2*COS(5*PI()/180)+SIN(5*PI()/180)) -> 1566.8613 | X27: =0.5*1.2*($T27*0.44704)^2*$C$3*$C$5+$C$4*9.81*($C$2*COS(10*PI()/180)+SIN(10*PI()/180)) -> 2488.9214 | Y27: =0.5*1.2*($T27*0.44704)^2*$C$3*$C$5+$C$4*9.81*($C$2*COS(15*PI()/180)+SIN(15*PI()/180)) -> 3395.582 | Z27: =0.5*1.2*($T27*0.44704)^2*$C$3*$C$5+$C$4*9.81*($C$2*COS(20*PI()/180)+SIN(20*PI()/180)) -> 4279.9428 | AA27: =0.5*1.2*($T27*0.44704)^2*$C$3*$C$5+$C$4*9.81*($C$2*COS(25*PI()/180)+SIN(25*PI()/180)) -> 5135.2733 | AB27: =0.5*1.2*($T27*0.44704)^2*$C$3*$C$5+$C$4*9.81*($C$2*COS(30*PI()/180)+SIN(30*PI()/180)) -> 5955.0639 | AE27: =PI()/30*$H27*$C$6/AD$2*2.23649 -> 22.045492 | AF27: =(0.5*1.2*(AE27*0.44704)^2*$C$3*$C$5+$C$4*9.81*($C$2*COS($C$7*PI()/180)+SIN($C$7*PI()/180)))*$C$6/AD$2 -> 6.8535139 | AG27: =AD$2*$I27/$C$6 -> 5237.484 | AJ27: =PI()/30*$H27*$C$6/AI$2*2.23649 -> 33.068238 | AK27: =(0.5*1.2*(AJ27*0.44704)^2*$C$3*$C$5+$C$4*9.81*($C$2*COS($C$7*PI()/180)+SIN($C$7*PI()/180)))*$C$6/AI$2 -> 12.727951 | AL27: =AI$2*$I27/$C$6 -> 3491.656 | AO27: =PI()/30*$H27*$C$6/AN$2*2.23649 -> 49.602357 | AP27: =(0.5*1.2*(AO27*0.44704)^2*$C$3*$C$5+$C$4*9.81*($C$2*COS($C$7*PI()/180)+SIN($C$7*PI()/180)))*$C$6/AN$2 -> 27.352845 | AQ27: =AN$2*$I27/$C$6 -> 2327.7706 | AT27: =PI()/30*$H27*$C$6/AS$2*2.23649 -> 66.136476 | AU27: =(0.5*1.2*(AT27*0.44704)^2*$C$3*$C$5+$C$4*9.81*($C$2*COS($C$7*PI()/180)+SIN($C$7*PI()/180)))*$C$6/AS$2 -> 51.890842 | AV27: =AS$2*$I27/$C$6 -> 1745.828 | AY27: =PI()/30*$H27*$C$6/AX$2*2.23649 -> 82.670594 | AZ27: =(0.5*1.2*(AY27*0.44704)^2*$C$3*$C$5+$C$4*9.81*($C$2*COS($C$7*PI()/180)+SIN($C$7*PI()/180)))*$C$6/AX$2 -> 89.646309 | BA27: =AX$2*$I27/$C$6 -> 1396.6624
H28: 3000 | I28: 170 | K28: =10000/($H28*PI()/30) -> 31.830989 | L28: =20000/($H28*PI()/30) -> 63.661977 | M28: =30000/($H28*PI()/30) -> 95.492966 | N28: =40000/($H28*PI()/30) -> 127.32395 | O28: =50000/($H28*PI()/30) -> 159.15494 | P28: =60000/($H28*PI()/30) -> 190.98593 | T28: 78 | U28: =70000/(T28*0.44704) -> 2007.5069 | V28: =0.5*1.2*($T28*0.44704)^2*$C$3*$C$5+$C$4*9.81*($C$2*COS(0*PI()/180)+SIN(0*PI()/180)) -> 674.40306 | W28: =0.5*1.2*($T28*0.44704)^2*$C$3*$C$5+$C$4*9.81*($C$2*COS(5*PI()/180)+SIN(5*PI()/180)) -> 1604.8453 | X28: =0.5*1.2*($T28*0.44704)^2*$C$3*$C$5+$C$4*9.81*($C$2*COS(10*PI()/180)+SIN(10*PI()/180)) -> 2526.9054 | Y28: =0.5*1.2*($T28*0.44704)^2*$C$3*$C$5+$C$4*9.81*($C$2*COS(15*PI()/180)+SIN(15*PI()/180)) -> 3433.5659 | Z28: =0.5*1.2*($T28*0.44704)^2*$C$3*$C$5+$C$4*9.81*($C$2*COS(20*PI()/180)+SIN(20*PI()/180)) -> 4317.9267 | AA28: =0.5*1.2*($T28*0.44704)^2*$C$3*$C$5+$C$4*9.81*($C$2*COS(25*PI()/180)+SIN(25*PI()/180)) -> 5173.2572 | AB28: =0.5*1.2*($T28*0.44704)^2*$C$3*$C$5+$C$4*9.81*($C$2*COS(30*PI()/180)+SIN(30*PI()/180)) -> 5993.0479 | AE28: =PI()/30*$H28*$C$6/AD$2*2.23649 -> 22.805681 | AF28: =(0.5*1.2*(AE28*0.44704)^2*$C$3*$C$5+$C$4*9.81*($C$2*COS($C$7*PI()/180)+SIN($C$7*PI()/180)))*$C$6/AD$2 -> 6.9450957 | AG28: =AD$2*$I28/$C$6 -> 5237.484 | AJ28: =PI()/30*$H28*$C$6/AI$2*2.23649 -> 34.208522 | AK28: =(0.5*1.2*(AJ28*0.44704)^2*$C$3*$C$5+$C$4*9.81*($C$2*COS($C$7*PI()/180)+SIN($C$7*PI()/180)))*$C$6/AI$2 -> 13.037039 | AL28: =AI$2*$I28/$C$6 -> 3491.656 | AO28: =PI()/30*$H28*$C$6/AN$2*2.23649 -> 51.312783 | AP28: =(0.5*1.2*(AO28*0.44704)^2*$C$3*$C$5+$C$4*9.81*($C$2*COS($C$7*PI()/180)+SIN($C$7*PI()/180)))*$C$6/AN$2 -> 28.396019 | AQ28: =AN$2*$I28/$C$6 -> 2327.7706 | AT28: =PI()/30*$H28*$C$6/AS$2*2.23649 -> 68.417044 | AU28: =(0.5*1.2*(AT28*0.44704)^2*$C$3*$C$5+$C$4*9.81*($C$2*COS($C$7*PI()/180)+SIN($C$7*PI()/180)))*$C$6/AS$2 -> 54.363551 | AV28: =AS$2*$I28/$C$6 -> 1745.828 | AY28: =PI()/30*$H28*$C$6/AX$2*2.23649 -> 85.521305 | AZ28: =(0.5*1.2*(AY28*0.44704)^2*$C$3*$C$5+$C$4*9.81*($C$2*COS($C$7*PI()/180)+SIN($C$7*PI()/180)))*$C$6/AX$2 -> 94.47582 | BA28: =AX$2*$I28/$C$6 -> 1396.6624
H29: 3100 | I29: 170 | K29: =10000/($H29*PI()/30) -> 30.804183 | L29: =20000/($H29*PI()/30) -> 61.608365 | M29: =30000/($H29*PI()/30) -> 92.412548 | N29: =40000/($H29*PI()/30) -> 123.21673 | O29: =50000/($H29*PI()/30) -> 154.02091 | P29: =60000/($H29*PI()/30) -> 184.8251 | T29: 81 | U29: =70000/(T29*0.44704) -> 1933.1548 | V29: =0.5*1.2*($T29*0.44704)^2*$C$3*$C$5+$C$4*9.81*($C$2*COS(0*PI()/180)+SIN(0*PI()/180)) -> 713.87658 | W29: =0.5*1.2*($T29*0.44704)^2*$C$3*$C$5+$C$4*9.81*($C$2*COS(5*PI()/180)+SIN(5*PI()/180)) -> 1644.3188 | X29: =0.5*1.2*($T29*0.44704)^2*$C$3*$C$5+$C$4*9.81*($C$2*COS(10*PI()/180)+SIN(10*PI()/180)) -> 2566.3789 | Y29: =0.5*1.2*($T29*0.44704)^2*$C$3*$C$5+$C$4*9.81*($C$2*COS(15*PI()/180)+SIN(15*PI()/180)) -> 3473.0395 | Z29: =0.5*1.2*($T29*0.44704)^2*$C$3*$C$5+$C$4*9.81*($C$2*COS(20*PI()/180)+SIN(20*PI()/180)) -> 4357.4002 | AA29: =0.5*1.2*($T29*0.44704)^2*$C$3*$C$5+$C$4*9.81*($C$2*COS(25*PI()/180)+SIN(25*PI()/180)) -> 5212.7307 | AB29: =0.5*1.2*($T29*0.44704)^2*$C$3*$C$5+$C$4*9.81*($C$2*COS(30*PI()/180)+SIN(30*PI()/180)) -> 6032.5214 | AE29: =PI()/30*$H29*$C$6/AD$2*2.23649 -> 23.565871 | AF29: =(0.5*1.2*(AE29*0.44704)^2*$C$3*$C$5+$C$4*9.81*($C$2*COS($C$7*PI()/180)+SIN($C$7*PI()/180)))*$C$6/AD$2 -> 7.039782 | AG29: =AD$2*$I29/$C$6 -> 5237.484 | AJ29: =PI()/30*$H29*$C$6/AI$2*2.23649 -> 35.348806 | AK29: =(0.5*1.2*(AJ29*0.44704)^2*$C$3*$C$5+$C$4*9.81*($C$2*COS($C$7*PI()/180)+SIN($C$7*PI()/180)))*$C$6/AI$2 -> 13.356606 | AL29: =AI$2*$I29/$C$6 -> 3491.656 | AO29: =PI()/30*$H29*$C$6/AN$2*2.23649 -> 53.023209 | AP29: =(0.5*1.2*(AO29*0.44704)^2*$C$3*$C$5+$C$4*9.81*($C$2*COS($C$7*PI()/180)+SIN($C$7*PI()/180)))*$C$6/AN$2 -> 29.474555 | AQ29: =AN$2*$I29/$C$6 -> 2327.7706 | AT29: =PI()/30*$H29*$C$6/AS$2*2.23649 -> 70.697612 | AU29: =(0.5*1.2*(AT29*0.44704)^2*$C$3*$C$5+$C$4*9.81*($C$2*COS($C$7*PI()/180)+SIN($C$7*PI()/180)))*$C$6/AS$2 -> 56.920081 | AV29: =AS$2*$I29/$C$6 -> 1745.828 | AY29: =PI()/30*$H29*$C$6/AX$2*2.23649 -> 88.372015 | AZ29: =(0.5*1.2*(AY29*0.44704)^2*$C$3*$C$5+$C$4*9.81*($C$2*COS($C$7*PI()/180)+SIN($C$7*PI()/180)))*$C$6/AX$2 -> 99.469043 | BA29: =AX$2*$I29/$C$6 -> 1396.6624
H30: 3200 | I30: 170 | K30: =10000/($H30*PI()/30) -> 29.841552 | L30: =20000/($H30*PI()/30) -> 59.683104 | M30: =30000/($H30*PI()/30) -> 89.524655 | N30: =40000/($H30*PI()/30) -> 119.36621 | O30: =50000/($H30*PI()/30) -> 149.20776 | P30: =60000/($H30*PI()/30) -> 179.04931 | T30: 84 | U30: =70000/(T30*0.44704) -> 1864.1136 | V30: =0.5*1.2*($T30*0.44704)^2*$C$3*$C$5+$C$4*9.81*($C$2*COS(0*PI()/180)+SIN(0*PI()/180)) -> 754.83967 | W30: =0.5*1.2*($T30*0.44704)^2*$C$3*$C$5+$C$4*9.81*($C$2*COS(5*PI()/180)+SIN(5*PI()/180)) -> 1685.2819 | X30: =0.5*1.2*($T30*0.44704)^2*$C$3*$C$5+$C$4*9.81*($C$2*COS(10*PI()/180)+SIN(10*PI()/180)) -> 2607.342 | Y30: =0.5*1.2*($T30*0.44704)^2*$C$3*$C$5+$C$4*9.81*($C$2*COS(15*PI()/180)+SIN(15*PI()/180)) -> 3514.0025 | Z30: =0.5*1.2*($T30*0.44704)^2*$C$3*$C$5+$C$4*9.81*($C$2*COS(20*PI()/180)+SIN(20*PI()/180)) -> 4398.3633 | AA30: =0.5*1.2*($T30*0.44704)^2*$C$3*$C$5+$C$4*9.81*($C$2*COS(25*PI()/180)+SIN(25*PI()/180)) -> 5253.6938 | AB30: =0.5*1.2*($T30*0.44704)^2*$C$3*$C$5+$C$4*9.81*($C$2*COS(30*PI()/180)+SIN(30*PI()/180)) -> 6073.4845 | AE30: =PI()/30*$H30*$C$6/AD$2*2.23649 -> 24.32606 | AF30: =(0.5*1.2*(AE30*0.44704)^2*$C$3*$C$5+$C$4*9.81*($C$2*COS($C$7*PI()/180)+SIN($C$7*PI()/180)))*$C$6/AD$2 -> 7.1375728 | AG30: =AD$2*$I30/$C$6 -> 5237.484 | AJ30: =PI()/30*$H30*$C$6/AI$2*2.23649 -> 36.48909 | AK30: =(0.5*1.2*(AJ30*0.44704)^2*$C$3*$C$5+$C$4*9.81*($C$2*COS($C$7*PI()/180)+SIN($C$7*PI()/180)))*$C$6/AI$2 -> 13.686649 | AL30: =AI$2*$I30/$C$6 -> 3491.656 | AO30: =PI()/30*$H30*$C$6/AN$2*2.23649 -> 54.733635 | AP30: =(0.5*1.2*(AO30*0.44704)^2*$C$3*$C$5+$C$4*9.81*($C$2*COS($C$7*PI()/180)+SIN($C$7*PI()/180)))*$C$6/AN$2 -> 30.588453 | AQ30: =AN$2*$I30/$C$6 -> 2327.7706 | AT30: =PI()/30*$H30*$C$6/AS$2*2.23649 -> 72.97818 | AU30: =(0.5*1.2*(AT30*0.44704)^2*$C$3*$C$5+$C$4*9.81*($C$2*COS($C$7*PI()/180)+SIN($C$7*PI()/180)))*$C$6/AS$2 -> 59.560432 | AV30: =AS$2*$I30/$C$6 -> 1745.828 | AY30: =PI()/30*$H30*$C$6/AX$2*2.23649 -> 91.222725 | AZ30: =(0.5*1.2*(AY30*0.44704)^2*$C$3*$C$5+$C$4*9.81*($C$2*COS($C$7*PI()/180)+SIN($C$7*PI()/180)))*$C$6/AX$2 -> 104.62598 | BA30: =AX$2*$I30/$C$6 -> 1396.6624
H31: 3300 | I31: 170 | K31: =10000/($H31*PI()/30) -> 28.937262 | L31: =20000/($H31*PI()/30) -> 57.874525 | M31: =30000/($H31*PI()/30) -> 86.811787 | N31: =40000/($H31*PI()/30) -> 115.74905 | O31: =50000/($H31*PI()/30) -> 144.68631 | P31: =60000/($H31*PI()/30) -> 173.62357 | Q31: =70000/($H31*PI()/30) -> 202.56084 | T31: 87 | U31: =70000/(T31*0.44704) -> 1799.8338 | V31: =0.5*1.2*($T31*0.44704)^2*$C$3*$C$5+$C$4*9.81*($C$2*COS(0*PI()/180)+SIN(0*PI()/180)) -> 797.29233 | W31: =0.5*1.2*($T31*0.44704)^2*$C$3*$C$5+$C$4*9.81*($C$2*COS(5*PI()/180)+SIN(5*PI()/180)) -> 1727.7345 | X31: =0.5*1.2*($T31*0.44704)^2*$C$3*$C$5+$C$4*9.81*($C$2*COS(10*PI()/180)+SIN(10*PI()/180)) -> 2649.7946 | Y31: =0.5*1.2*($T31*0.44704)^2*$C$3*$C$5+$C$4*9.81*($C$2*COS(15*PI()/180)+SIN(15*PI()/180)) -> 3556.4552 | Z31: =0.5*1.2*($T31*0.44704)^2*$C$3*$C$5+$C$4*9.81*($C$2*COS(20*PI()/180)+SIN(20*PI()/180)) -> 4440.816 | AA31: =0.5*1.2*($T31*0.44704)^2*$C$3*$C$5+$C$4*9.81*($C$2*COS(25*PI()/180)+SIN(25*PI()/180)) -> 5296.1465 | AB31: =0.5*1.2*($T31*0.44704)^2*$C$3*$C$5+$C$4*9.81*($C$2*COS(30*PI()/180)+SIN(30*PI()/180)) -> 6115.9371 | AE31: =PI()/30*$H31*$C$6/AD$2*2.23649 -> 25.086249 | AF31: =(0.5*1.2*(AE31*0.44704)^2*$C$3*$C$5+$C$4*9.81*($C$2*COS($C$7*PI()/180)+SIN($C$7*PI()/180)))*$C$6/AD$2 -> 7.2384681 | AG31: =AD$2*$I31/$C$6 -> 5237.484 | AJ31: =PI()/30*$H31*$C$6/AI$2*2.23649 -> 37.629374 | AK31: =(0.5*1.2*(AJ31*0.44704)^2*$C$3*$C$5+$C$4*9.81*($C$2*COS($C$7*PI()/180)+SIN($C$7*PI()/180)))*$C$6/AI$2 -> 14.027171 | AL31: =AI$2*$I31/$C$6 -> 3491.656 | AO31: =PI()/30*$H31*$C$6/AN$2*2.23649 -> 56.444061 | AP31: =(0.5*1.2*(AO31*0.44704)^2*$C$3*$C$5+$C$4*9.81*($C$2*COS($C$7*PI()/180)+SIN($C$7*PI()/180)))*$C$6/AN$2 -> 31.737713 | AQ31: =AN$2*$I31/$C$6 -> 2327.7706 | AT31: =PI()/30*$H31*$C$6/AS$2*2.23649 -> 75.258748 | AU31: =(0.5*1.2*(AT31*0.44704)^2*$C$3*$C$5+$C$4*9.81*($C$2*COS($C$7*PI()/180)+SIN($C$7*PI()/180)))*$C$6/AS$2 -> 62.284604 | AV31: =AS$2*$I31/$C$6 -> 1745.828 | AY31: =PI()/30*$H31*$C$6/AX$2*2.23649 -> 94.073435 | AZ31: =(0.5*1.2*(AY31*0.44704)^2*$C$3*$C$5+$C$4*9.81*($C$2*COS($C$7*PI()/180)+SIN($C$7*PI()/180)))*$C$6/AX$2 -> 109.94663 | BA31: =AX$2*$I31/$C$6 -> 1396.6624
H32: 3400 | I32: 170 | K32: =10000/($H32*PI()/30) -> 28.086166 | L32: =20000/($H32*PI()/30) -> 56.172333 | M32: =30000/($H32*PI()/30) -> 84.258499 | N32: =40000/($H32*PI()/30) -> 112.34467 | O32: =50000/($H32*PI()/30) -> 140.43083 | P32: =60000/($H32*PI()/30) -> 168.517 | Q32: =70000/($H32*PI()/30) -> 196.60316 | T32: 90 | U32: =70000/(T32*0.44704) -> 1739.8393 | V32: =0.5*1.2*($T32*0.44704)^2*$C$3*$C$5+$C$4*9.81*($C$2*COS(0*PI()/180)+SIN(0*PI()/180)) -> 841.23455 | W32: =0.5*1.2*($T32*0.44704)^2*$C$3*$C$5+$C$4*9.81*($C$2*COS(5*PI()/180)+SIN(5*PI()/180)) -> 1771.6768 | X32: =0.5*1.2*($T32*0.44704)^2*$C$3*$C$5+$C$4*9.81*($C$2*COS(10*PI()/180)+SIN(10*PI()/180)) -> 2693.7369 | Y32: =0.5*1.2*($T32*0.44704)^2*$C$3*$C$5+$C$4*9.81*($C$2*COS(15*PI()/180)+SIN(15*PI()/180)) -> 3600.3974 | Z32: =0.5*1.2*($T32*0.44704)^2*$C$3*$C$5+$C$4*9.81*($C$2*COS(20*PI()/180)+SIN(20*PI()/180)) -> 4484.7582 | AA32: =0.5*1.2*($T32*0.44704)^2*$C$3*$C$5+$C$4*9.81*($C$2*COS(25*PI()/180)+SIN(25*PI()/180)) -> 5340.0887 | AB32: =0.5*1.2*($T32*0.44704)^2*$C$3*$C$5+$C$4*9.81*($C$2*COS(30*PI()/180)+SIN(30*PI()/180)) -> 6159.8793 | AE32: =PI()/30*$H32*$C$6/AD$2*2.23649 -> 25.846439 | AF32: =(0.5*1.2*(AE32*0.44704)^2*$C$3*$C$5+$C$4*9.81*($C$2*COS($C$7*PI()/180)+SIN($C$7*PI()/180)))*$C$6/AD$2 -> 7.3424678 | AG32: =AD$2*$I32/$C$6 -> 5237.484 | AJ32: =PI()/30*$H32*$C$6/AI$2*2.23649 -> 38.769658 | AK32: =(0.5*1.2*(AJ32*0.44704)^2*$C$3*$C$5+$C$4*9.81*($C$2*COS($C$7*PI()/180)+SIN($C$7*PI()/180)))*$C$6/AI$2 -> 14.37817 | AL32: =AI$2*$I32/$C$6 -> 3491.656 | AO32: =PI()/30*$H32*$C$6/AN$2*2.23649 -> 58.154487 | AP32: =(0.5*1.2*(AO32*0.44704)^2*$C$3*$C$5+$C$4*9.81*($C$2*COS($C$7*PI()/180)+SIN($C$7*PI()/180)))*$C$6/AN$2 -> 32.922335 | AQ32: =AN$2*$I32/$C$6 -> 2327.7706 | AT32: =PI()/30*$H32*$C$6/AS$2*2.23649 -> 77.539316 | AU32: =(0.5*1.2*(AT32*0.44704)^2*$C$3*$C$5+$C$4*9.81*($C$2*COS($C$7*PI()/180)+SIN($C$7*PI()/180)))*$C$6/AS$2 -> 65.092596 | AV32: =AS$2*$I32/$C$6 -> 1745.828 | AY32: =PI()/30*$H32*$C$6/AX$2*2.23649 -> 96.924145 | AZ32: =(0.5*1.2*(AY32*0.44704)^2*$C$3*$C$5+$C$4*9.81*($C$2*COS($C$7*PI()/180)+SIN($C$7*PI()/180)))*$C$6/AX$2 -> 115.43098 | BA32: =AX$2*$I32/$C$6 -> 1396.6624
H33: 3500 | I33: 170 | K33: =10000/($H33*PI()/30) -> 27.283705 | L33: =20000/($H33*PI()/30) -> 54.567409 | M33: =30000/($H33*PI()/30) -> 81.851114 | N33: =40000/($H33*PI()/30) -> 109.13482 | O33: =50000/($H33*PI()/30) -> 136.41852 | P33: =60000/($H33*PI()/30) -> 163.70223 | Q33: =70000/($H33*PI()/30) -> 190.98593 | T33: 93 | U33: =70000/(T33*0.44704) -> 1683.7155 | V33: =0.5*1.2*($T33*0.44704)^2*$C$3*$C$5+$C$4*9.81*($C$2*COS(0*PI()/180)+SIN(0*PI()/180)) -> 886.66634 | W33: =0.5*1.2*($T33*0.44704)^2*$C$3*$C$5+$C$4*9.81*($C$2*COS(5*PI()/180)+SIN(5*PI()/180)) -> 1817.1085 | X33: =0.5*1.2*($T33*0.44704)^2*$C$3*$C$5+$C$4*9.81*($C$2*COS(10*PI()/180)+SIN(10*PI()/180)) -> 2739.1686 | Y33: =0.5*1.2*($T33*0.44704)^2*$C$3*$C$5+$C$4*9.81*($C$2*COS(15*PI()/180)+SIN(15*PI()/180)) -> 3645.8292 | Z33: =0.5*1.2*($T33*0.44704)^2*$C$3*$C$5+$C$4*9.81*($C$2*COS(20*PI()/180)+SIN(20*PI()/180)) -> 4530.19 | AA33: =0.5*1.2*($T33*0.44704)^2*$C$3*$C$5+$C$4*9.81*($C$2*COS(25*PI()/180)+SIN(25*PI()/180)) -> 5385.5205 | AB33: =0.5*1.2*($T33*0.44704)^2*$C$3*$C$5+$C$4*9.81*($C$2*COS(30*PI()/180)+SIN(30*PI()/180)) -> 6205.3111 | AE33: =PI()/30*$H33*$C$6/AD$2*2.23649 -> 26.606628 | AF33: =(0.5*1.2*(AE33*0.44704)^2*$C$3*$C$5+$C$4*9.81*($C$2*COS($C$7*PI()/180)+SIN($C$7*PI()/180)))*$C$6/AD$2 -> 7.4495719 | AG33: =AD$2*$I33/$C$6 -> 5237.484 | AJ33: =PI()/30*$H33*$C$6/AI$2*2.23649 -> 39.909942 | AK33: =(0.5*1.2*(AJ33*0.44704)^2*$C$3*$C$5+$C$4*9.81*($C$2*COS($C$7*PI()/180)+SIN($C$7*PI()/180)))*$C$6/AI$2 -> 14.739646 | AL33: =AI$2*$I33/$C$6 -> 3491.656 | AO33: =PI()/30*$H33*$C$6/AN$2*2.23649 -> 59.864913 | AP33: =(0.5*1.2*(AO33*0.44704)^2*$C$3*$C$5+$C$4*9.81*($C$2*COS($C$7*PI()/180)+SIN($C$7*PI()/180)))*$C$6/AN$2 -> 34.142318 | AQ33: =AN$2*$I33/$C$6 -> 2327.7706 | AT33: =PI()/30*$H33*$C$6/AS$2*2.23649 -> 79.819884 | AU33: =(0.5*1.2*(AT33*0.44704)^2*$C$3*$C$5+$C$4*9.81*($C$2*COS($C$7*PI()/180)+SIN($C$7*PI()/180)))*$C$6/AS$2 -> 67.984409 | AV33: =AS$2*$I33/$C$6 -> 1745.828 | AY33: =PI()/30*$H33*$C$6/AX$2*2.23649 -> 99.774855 | AZ33: =(0.5*1.2*(AY33*0.44704)^2*$C$3*$C$5+$C$4*9.81*($C$2*COS($C$7*PI()/180)+SIN($C$7*PI()/180)))*$C$6/AX$2 -> 121.07906 | BA33: =AX$2*$I33/$C$6 -> 1396.6624
